Workbook

Sheet 01_전체조닝63
A2: 성수 약국 조닝 · 제작도면 반영
A3: 2026.09.17 | 63모듈·315단 | 우선 326 SKU (A 106 / B 208 / T 12) | 391F 계획 · 재고수량 아님
A4: 확인 순서: 03 전체상품 → 05 상품별 배치(F 입력) → 06 집기 실측 → 02 선반 합계. 실제 발주·규격·포장 치수는 미확정.
A6: 모듈 | B6: 방향 | C6: 주테마 | D6: 매대명 | E6: 역할 | F6: 브랜드 운영 | G6: S1 최상단 | H6: S2 | I6: S3 | J6: S4 | K6: S5 최하단 | L6: 선반 수 | M6: 오픈 진열단 | N6: 테마 진열단 | O6: 시험·여유단 | P6: 안내단 | Q6: 운영 메모 | R6: 제작도면 집기 | S6: 총높이 mm | T6: 진열 SKU행 | U6: 계획 총F | V6: 치수 근거
A7: W1 | B7: 상단 벽면 | C7: 피부약·상처 보호 | D7: Skin Treatments | E7: 피부 고관여 상담 | G7: PDRN 분류·상담 안내 | H7: PDRN 일반의약품 | I7: 가려움·피부염 외용약 | J7: 피부 상담약 확장 여유 | K7: MD 보호재·의료기기 분리 | L7: 5 | M7: 3 | N7: 0 | O7: 1 | P7: 1 | Q7: 외용약 상담은 중단, MD는 분리 선반. W1·W2 외용/더마 2면, W4·W5 영양/선물 2면, W3 가변 1면 유지. | R7: P-2F-04 | S7: 2400 | T7: =SUMIFS('02_선반315'!$P$7:$P$321,'02_선반315'!$B$7:$B$321,A7) -> 5 | U7: =SUMIFS('02_선반315'!$Q$7:$Q$321,'02_선반315'!$B$7:$B$321,A7) -> 6 | V7: PDF p5~6 (2026-08-11)
A8: W2 | B8: 상단 벽면 | C8: 더마·세정·선케어 | D8: Dermocosmetics | E8: EGF·프리미엄 비교 | F8: EGFx S2, 프로캄 S3의 선반 블록 | G8: EGF 화장품 제형 안내 | H8: EGFx 앰플 비교 | I8: 프로캄·이지듀 EGF 크림 | J8: EGF·PDRN 마스크 | K8: 프리미엄 추가 규격 여유 | L8: 5 | M8: 3 | N8: 0 | O8: 1 | P8: 1 | Q8: W2는 상담형 EGF 비교. 일상 보습과 주름·탄력의 주 진열은 G5. | R8: P-2F-04 | S8: 2400 | T8: =SUMIFS('02_선반315'!$P$7:$P$321,'02_선반315'!$B$7:$B$321,A8) -> 6 | U8: =SUMIFS('02_선반315'!$Q$7:$Q$321,'02_선반315'!$B$7:$B$321,A8) -> 7 | V8: PDF p5~6 (2026-08-11)
A9: W3 | B9: 상단 벽면 | C9: 추천·상담 안내 | D9: Seasonal Picks | E9: 월별 선택 테마 | G9: 환절기 보습 테마 | H9: 진정 크림 테마 | I9: 장벽 세럼 테마 | J9: 립 보습 연결 | K9: 다음 테마 교체 여유 | L9: 5 | M9: 0 | N9: 3 | O9: 1 | P9: 1 | Q9: Best Sellers는 실적 근거가 생긴 뒤 사용. 브랜드 매입조건만으로 추천 표현을 쓰지 않음. | R9: P-2F-04 | S9: 2400 | T9: =SUMIFS('02_선반315'!$P$7:$P$321,'02_선반315'!$B$7:$B$321,A9) -> 3 | U9: =SUMIFS('02_선반315'!$Q$7:$Q$321,'02_선반315'!$B$7:$B$321,A9) -> 3 | V9: PDF p5~6 (2026-08-11)
A10: W4 | B10: 상단 벽면 | C10: 영양·건강 선물 | D10: Daily Vitamins | E10: 경구 영양·약사 상담 | G10: 경구 영양 상담 안내 | H10: 비타민B 의약품 | I10: 마그네슘 경구제품 | J10: 글루타치온 의약품 | K10: 피로·간·한방 상담약 | L10: 5 | M10: 4 | N10: 0 | O10: 0 | P10: 1 | Q10: 식품형 비타민·오메가3 등은 G4. 정규 포장 하나를 기본으로 하고 큰 포장을 별도 전면 반복하지 않음. | R10: P-2F-04 | S10: 2400 | T10: =SUMIFS('02_선반315'!$P$7:$P$321,'02_선반315'!$B$7:$B$321,A10) -> 10 | U10: =SUMIFS('02_선반315'!$Q$7:$Q$321,'02_선반315'!$B$7:$B$321,A10) -> 10 | V10: PDF p5~6 (2026-08-11)
A11: W5 | B11: 상단 벽면 | C11: 영양·건강 선물 | D11: Wellness Gifts | E11: 건강 선물 본진 | F11: 정원삼 중심 선택형 브랜드존 | G11: 정규 선물 구성 안내 | H11: 멀티비타민 정규 세트 | I11: 홍삼 30포 비교 | J11: 콜라겐·홍삼 젤리 | K11: 다매 홍삼·절편 | L11: 5 | M11: 4 | N11: 0 | O11: 0 | P11: 1 | Q11: 첨부에는 정원삼이 있으며 정관장으로 대체 표기하지 않음. 5단 모두 상설 입고를 뜻하지 않음. | R11: P-2F-04 | S11: 2400 | T11: =SUMIFS('02_선반315'!$P$7:$P$321,'02_선반315'!$B$7:$B$321,A11) -> 8 | U11: =SUMIFS('02_선반315'!$Q$7:$Q$321,'02_선반315'!$B$7:$B$321,A11) -> 8 | V11: PDF p5~6 (2026-08-11)
A12: L1 | B12: 좌측 벽면 | C12: 일반약·여행·생활 | D12: Cold & Allergy | E12: 일반약 실용 구색 | G12: 알레르기 정제·낮은 포장 | H12: 감기 주간·야간 구분 | I12: 기침·인후 제형 | J12: 코 증상 스프레이 | K12: 어린이 여행 상담 | L12: 5 | M12: 5 | N12: 0 | O12: 0 | P12: 0 | R12: P-2F-05 | S12: 1700 | T12: =SUMIFS('02_선반315'!$P$7:$P$321,'02_선반315'!$B$7:$B$321,A12) -> 14 | U12: =SUMIFS('02_선반315'!$Q$7:$Q$321,'02_선반315'!$B$7:$B$321,A12) -> 14 | V12: PDF p7 (2026-08-07)
A13: L2 | B13: 좌측 벽면 | C13: 일반약·여행·생활 | D13: Stomach & Travel | E13: 소화·배변·이동 상담 | G13: 소화 정제·낮은 포장 | H13: 소화·속 불편 액상 | I13: 설사 상담 | J13: 변비 상담 | K13: 멀미·이동 상담 | L13: 5 | M13: 5 | N13: 0 | O13: 0 | P13: 0 | R13: P-2F-05 | S13: 1700 | T13: =SUMIFS('02_선반315'!$P$7:$P$321,'02_선반315'!$B$7:$B$321,A13) -> 14 | U13: =SUMIFS('02_선반315'!$Q$7:$Q$321,'02_선반315'!$B$7:$B$321,A13) -> 14 | V13: PDF p7 (2026-08-07)
A14: L3 | B14: 좌측 벽면 | C14: 일반약·여행·생활 | D14: Pain Relief | E14: 진통·파스 본진 | G14: 해열·진통 소포장 | H14: 파스 기본·롱 규격 | I14: 코인·쿨 타입 | J14: 바르는 진통 제형 | K14: 분사형·큰 포장 | L14: 5 | M14: 5 | N14: 0 | O14: 0 | P14: 0 | R14: P-2F-05 | S14: 1700 | T14: =SUMIFS('02_선반315'!$P$7:$P$321,'02_선반315'!$B$7:$B$321,A14) -> 14 | U14: =SUMIFS('02_선반315'!$Q$7:$Q$321,'02_선반315'!$B$7:$B$321,A14) -> 16 | V14: PDF p7 (2026-08-07)
A15: L4 | B15: 좌측 벽면 | C15: 립·눈·다리·구강 | D15: Oral Care | E15: 구강 위생·상담 | G15: 구내염 상담·낮은 포장 | H15: 잇몸·불소 치약 | I15: 휴대 가글·구강 스프레이 | J15: 칫솔·치실·혀 세정 | K15: 일상 가글 큰 포장 | L15: 5 | M15: 5 | N15: 0 | O15: 0 | P15: 0 | R15: P-2F-05 | S15: 1700 | T15: =SUMIFS('02_선반315'!$P$7:$P$321,'02_선반315'!$B$7:$B$321,A15) -> 11 | U15: =SUMIFS('02_선반315'!$Q$7:$Q$321,'02_선반315'!$B$7:$B$321,A15) -> 11 | V15: PDF p7 (2026-08-07)
A16: B1 | B16: entry | C16: 피부약·상처 보호 | D16: Acne Care | E16: 좌측 진입의 여드름 안내 | G16: 선택 안내 | H16: 면포성 여드름 외용제 / 붉은 여드름 외용제 | I16: 스팟 보호 패치 | J16: 스팟 보호 패치 | K16: 추가 도입 여유 | L16: 5 | M16: 0 | N16: 3 | O16: 1 | P16: 1 | Q16: 본진으로 안내하는 입구 매대. 여드름 전제품 복제 진열 금지. | R16: P-2F-05 | S16: 1700 | T16: =SUMIFS('02_선반315'!$P$7:$P$321,'02_선반315'!$B$7:$B$321,A16) -> 4 | U16: =SUMIFS('02_선반315'!$Q$7:$Q$321,'02_선반315'!$B$7:$B$321,A16) -> 4 | V16: PDF p7 (2026-08-07)
A17: B2 | B17: entry | C17: 피부약·상처 보호 | D17: Scar & Wound | E17: 흉터와 상처의 차이 | G17: 선택 안내 | H17: 흉터 외용제 | I17: 실리콘 흉터관리 제품 | J17: 일반·방수 밴드 | K17: 추가 도입 여유 | L17: 5 | M17: 0 | N17: 3 | O17: 1 | P17: 1 | R17: P-2F-05 | S17: 1700 | T17: =SUMIFS('02_선반315'!$P$7:$P$321,'02_선반315'!$B$7:$B$321,A17) -> 3 | U17: =SUMIFS('02_선반315'!$Q$7:$Q$321,'02_선반315'!$B$7:$B$321,A17) -> 3 | V17: PDF p7 (2026-08-07)
A18: B3 | B18: entry | C18: 일반약·여행·생활 | D18: Travel Essentials | E18: 여행 위생용품 본진 | G18: 여행 위생 안내 | H18: 마스크·호흡기 위생 | I18: 수면 안대 | J18: 접이식 여행컵 | K18: 벌레 기피용품 | L18: 5 | M18: 4 | N18: 0 | O18: 0 | P18: 1 | R18: P-2F-05 | S18: 1700 | T18: =SUMIFS('02_선반315'!$P$7:$P$321,'02_선반315'!$B$7:$B$321,A18) -> 6 | U18: =SUMIFS('02_선반315'!$Q$7:$Q$321,'02_선반315'!$B$7:$B$321,A18) -> 6 | V18: PDF p7 (2026-08-07)
A19: B4 | B19: entry | C19: 추천·상담 안내 | D19: Skin Care Finder | E19: 입구의 고민 길찾기 | G19: 피부 고민 선택 안내 | H19: A 여드름·피지 / B 톤 | I19: C 보습 / D 진정 / E 탄력 | J19: 약사 상담 결과·주 진열 지도 | K19: 후속 상담 도구 여유 | L19: 5 | M19: 0 | N19: 0 | O19: 0 | P19: 5 | R19: P-2F-05 | S19: 1700 | T19: =SUMIFS('02_선반315'!$P$7:$P$321,'02_선반315'!$B$7:$B$321,A19) -> 0 | U19: =SUMIFS('02_선반315'!$Q$7:$Q$321,'02_선반315'!$B$7:$B$321,A19) -> 0 | V19: PDF p7 (2026-08-07)
A20: B5 | B20: entry | C20: 영양·건강 선물 | D20: Wellness & Gifts | E20: 영양·선물 탐색 | G20: 선택 안내 | H20: 비타민C 경구제품 | I20: 콜라겐·이너뷰티 | J20: 홍삼 제품 | K20: 추가 도입 여유 | L20: 5 | M20: 0 | N20: 3 | O20: 1 | P20: 1 | R20: P-2F-05 | S20: 1700 | T20: =SUMIFS('02_선반315'!$P$7:$P$321,'02_선반315'!$B$7:$B$321,A20) -> 3 | U20: =SUMIFS('02_선반315'!$Q$7:$Q$321,'02_선반315'!$B$7:$B$321,A20) -> 3 | V20: PDF p7 (2026-08-07)
A21: B6 | B21: entry | C21: 더마·세정·선케어 | D21: PDRN Skincare | E21: 우측 진입의 성분 탐색 | G21: 선택 안내 | H21: PDRN 스킨케어 | I21: PDRN 스킨케어 | J21: PDRN 스킨케어 | K21: 추가 도입 여유 | L21: 5 | M21: 0 | N21: 3 | O21: 1 | P21: 1 | Q21: 브랜드 독립 매대가 아니라 PDRN 탐색. 본진과 두 곳 모두 전체 브랜드존으로 운영하지 않음. | R21: P-2F-05 | S21: 1700 | T21: =SUMIFS('02_선반315'!$P$7:$P$321,'02_선반315'!$B$7:$B$321,A21) -> 3 | U21: =SUMIFS('02_선반315'!$Q$7:$Q$321,'02_선반315'!$B$7:$B$321,A21) -> 3 | V21: PDF p7 (2026-08-07)
A22: B7 | B22: entry | C22: 더마·세정·선케어 | D22: Barrier & Calm | E22: 건조·민감 첫 선택 | G22: 선택 안내 | H22: 장벽·보습 스킨케어 | I22: 진정 스킨케어 | J22: 수분 스킨케어 | K22: 추가 도입 여유 | L22: 5 | M22: 0 | N22: 3 | O22: 1 | P22: 1 | R22: P-2F-05 | S22: 1700 | T22: =SUMIFS('02_선반315'!$P$7:$P$321,'02_선반315'!$B$7:$B$321,A22) -> 3 | U22: =SUMIFS('02_선반315'!$Q$7:$Q$321,'02_선반315'!$B$7:$B$321,A22) -> 3 | V22: PDF p7 (2026-08-07)
A23: B8 | B23: entry | C23: 추천·상담 안내 | D23: New & Trial | E23: 신규 브랜드 한 테마 | G23: 시험 브랜드·기간 안내 | H23: 톰 CPR 세럼 시험 | I23: 톰 NMN 세럼 시험 | J23: 톰 NMN 크림 시험 | K23: 다음 브랜드 시험 여유 | L23: 5 | M23: 0 | N23: 0 | O23: 4 | P23: 1 | Q23: 판매·문의가 검증되면 적합한 본진으로 편입하고 B8에서는 교체. | R23: P-2F-05 | S23: 1700 | T23: =SUMIFS('02_선반315'!$P$7:$P$321,'02_선반315'!$B$7:$B$321,A23) -> 3 | U23: =SUMIFS('02_선반315'!$Q$7:$Q$321,'02_선반315'!$B$7:$B$321,A23) -> 3 | V23: PDF p7 (2026-08-07)
A24: G1-D-1 | B24: 하면·입구 방향 | C24: 피부약·상처 보호 | D24: 여드름 외용제 | E24: 상태별 선택 | G24: 현재 피부 상태 확인 | H24: 면포성 여드름 외용약 | I24: 붉은 여드름 외용약 | J24: 다른 성분 여드름약 | K24: 기타 여드름약 비교 | L24: 5 | M24: 4 | N24: 0 | O24: 0 | P24: 1 | Q24: 여드름약은 이 모듈에 집중. 아문 흉터는 G2-D-1로 분리. | R24: P-2F-02 / -02-1 | S24: 1700 | T24: =SUMIFS('02_선반315'!$P$7:$P$321,'02_선반315'!$B$7:$B$321,A24) -> 8 | U24: =SUMIFS('02_선반315'!$Q$7:$Q$321,'02_선반315'!$B$7:$B$321,A24) -> 10 | V24: PDF p3~4 (2026-08-11)
A25: G1-D-2 | B25: 하면·입구 방향 | C25: 피부약·상처 보호 | D25: 스팟 보호 패치 | E25: 형태별 선택 | F25: 선택한 패치 브랜드 내 1~2단 연속 블록 | G25: 패치 용도·피부 상태 안내 | H25: 일상 스팟 보호 패치 | I25: 국소 패치·다른 소재 | J25: 카밍·스팟 패치 비교 | K25: 다매 포장·대체 비교 | L25: 5 | M25: 4 | N25: 0 | O25: 0 | P25: 1 | R25: P-2F-02 / -02-1 | S25: 1700 | T25: =SUMIFS('02_선반315'!$P$7:$P$321,'02_선반315'!$B$7:$B$321,A25) -> 9 | U25: =SUMIFS('02_선반315'!$Q$7:$Q$321,'02_선반315'!$B$7:$B$321,A25) -> 10 | V25: PDF p3~4 (2026-08-11)
A26: G1-D-3 | B26: 하면·입구 방향 | C26: 더마·세정·선케어 | D26: A 피지·모공 | E26: Pores & Spot Care | G26: 피지·모공 고민 안내 | H26: 지성 피부 크림·겔 | I26: 피지 고민 세럼 | J26: 국소 스팟 화장품 | K26: 피지 케어 보완 제형 | L26: 5 | M26: 4 | N26: 0 | O26: 0 | P26: 1 | R26: P-2F-02 / -02-1 | S26: 1700 | T26: =SUMIFS('02_선반315'!$P$7:$P$321,'02_선반315'!$B$7:$B$321,A26) -> 7 | U26: =SUMIFS('02_선반315'!$Q$7:$Q$321,'02_선반315'!$B$7:$B$321,A26) -> 7 | V26: PDF p3~4 (2026-08-11)
A27: G1-U-1 | B27: 상면·POS 방향 | C27: 더마·세정·선케어 | D27: 피부타입별 세안 | E27: 클렌징 본진 | F27: 브랜드보다 젤·폼·오일·밀크 구분 우선 | G27: 세정 제형 선택 | H27: 젤리폼·폼 클렌저 | I27: 클렌징 오일 비교 | J27: 다른 세정 제형 | K27: 큰 포장 세정 제품 | L27: 5 | M27: 4 | N27: 0 | O27: 0 | P27: 1 | R27: P-2F-02 / -02-1 | S27: 1700 | T27: =SUMIFS('02_선반315'!$P$7:$P$321,'02_선반315'!$B$7:$B$321,A27) -> 7 | U27: =SUMIFS('02_선반315'!$Q$7:$Q$321,'02_선반315'!$B$7:$B$321,A27) -> 7 | V27: PDF p3~4 (2026-08-11)
A28: G1-U-2 | B28: 상면·POS 방향 | C28: 더마·세정·선케어 | D28: 세정·각질 제형 비교 | E28: 과도한 각질 관리 방지 | G28: 각질·필링 사용제품 확인 | H28: 국소 필링 스틱 | I28: 필링 토너·시험 | J28: 필링 세럼·시험 | K28: 필링 팩·시험 | L28: 5 | M28: 1 | N28: 0 | O28: 3 | P28: 1 | R28: P-2F-02 / -02-1 | S28: 1700 | T28: =SUMIFS('02_선반315'!$P$7:$P$321,'02_선반315'!$B$7:$B$321,A28) -> 4 | U28: =SUMIFS('02_선반315'!$Q$7:$Q$321,'02_선반315'!$B$7:$B$321,A28) -> 4 | V28: PDF p3~4 (2026-08-11)
A29: G1-U-3 | B29: 상면·POS 방향 | C29: 더마·세정·선케어 | D29: Body Care & Treatments | E29: 바디 전용 선택 | G29: 몸 고민·제품 분류 안내 | H29: 바디 미스트 화장품 | I29: 바디 세정 기본 | J29: 바디 세정 비교 | K29: 몸 여드름 외용약·별도표지 | L29: 5 | M29: 4 | N29: 0 | O29: 0 | P29: 1 | Q29: 몸 여드름 의약품은 S5 단독 표지. 위 화장품·세정 선반과 구분. | R29: P-2F-02 / -02-1 | S29: 1700 | T29: =SUMIFS('02_선반315'!$P$7:$P$321,'02_선반315'!$B$7:$B$321,A29) -> 5 | U29: =SUMIFS('02_선반315'!$Q$7:$Q$321,'02_선반315'!$B$7:$B$321,A29) -> 5 | V29: PDF p3~4 (2026-08-11)
A30: G2-D-1 | B30: 하면·입구 방향 | C30: 피부약·상처 보호 | D30: 아문 흉터 비교 | E30: Scar Care | G30: 아문 흉터와 열린 상처 구분 | H30: 흉터 외용 의약품 | I30: 실리콘 흉터관리 제품 | J30: 다른 흉터 외용약 | K30: 추가 소재·규격 여유 | L30: 5 | M30: 3 | N30: 0 | O30: 1 | P30: 1 | Q30: 기준안 G2-D-1과 G2-D-2 통합. 의약품·실리콘 제품의 선반 구분을 유지한다. | R30: P-2F-02 / -02-1 | S30: 1700 | T30: =SUMIFS('02_선반315'!$P$7:$P$321,'02_선반315'!$B$7:$B$321,A30) -> 5 | U30: =SUMIFS('02_선반315'!$Q$7:$Q$321,'02_선반315'!$B$7:$B$321,A30) -> 6 | V30: PDF p3~4 (2026-08-11)
A31: G2-D-2 | B31: 하면·입구 방향 | C31: 피부약·상처 보호 | D31: 일반·방수 밴드 | E31: Everyday Dressings | G31: 부위·방수 필요 안내 | H31: 일반 소형·중형·혼합 | I31: 방수 소형·중형·대형 | J31: 손끝 전용 | K31: 발뒤꿈치·도트형 | L31: 5 | M31: 4 | N31: 0 | O31: 0 | P31: 1 | Q31: 기준안 G2-D-3의 일반·방수 밴드를 이관. 브랜드 내 규격 비교는 허용하되 전 규격 입고는 보류. | R31: P-2F-02 / -02-1 | S31: 1700 | T31: =SUMIFS('02_선반315'!$P$7:$P$321,'02_선반315'!$B$7:$B$321,A31) -> 10 | U31: =SUMIFS('02_선반315'!$Q$7:$Q$321,'02_선반315'!$B$7:$B$321,A31) -> 10 | V31: PDF p3~4 (2026-08-11)
A32: G2-D-3 | B32: 하면·입구 방향 | C32: 피부약·상처 보호 | D32: 습윤 드레싱 | E32: Moist Dressings | F32: 케어리브 선택형 브랜드존 | G32: 습윤 드레싱 사용 상태 안내 | H32: 작은 상처·중형 | I32: 대형·빅사이즈 | J32: 발뒤꿈치 습윤형 | K32: 추가 포장 규격 여유 | L32: 5 | M32: 3 | N32: 0 | O32: 1 | P32: 1 | Q32: 기준안 G2-U-3의 드레싱만 이관. 소독·세정 제품은 G2-U-1로 이동. | R32: P-2F-02 / -02-1 | S32: 1700 | T32: =SUMIFS('02_선반315'!$P$7:$P$321,'02_선반315'!$B$7:$B$321,A32) -> 5 | U32: =SUMIFS('02_선반315'!$Q$7:$Q$321,'02_선반315'!$B$7:$B$321,A32) -> 5 | V32: PDF p3~4 (2026-08-11)
A33: G2-U-1 | B33: 상면·POS 방향 | C33: 피부약·상처 보호 | D33: 상처 외용·세정 | E33: Wound Care | G33: 상처 상태 상담 안내 | H33: 상처 항균 외용약 | I33: 상처·피부손상 외용약 | J33: 액상 소독·세정 | K33: 휴대 소독 스왑 | L33: 5 | M33: 4 | N33: 0 | O33: 0 | P33: 1 | Q33: 상처 상담 과정은 한 곳에서 하되 외용약·소독·드레싱은 선반과 모듈로 구분. PDRN 의약품·MD는 W1. | R33: P-2F-02 / -02-1 | S33: 1700 | T33: =SUMIFS('02_선반315'!$P$7:$P$321,'02_선반315'!$B$7:$B$321,A33) -> 8 | U33: =SUMIFS('02_선반315'!$Q$7:$Q$321,'02_선반315'!$B$7:$B$321,A33) -> 8 | V33: PDF p3~4 (2026-08-11)
A34: G2-U-2 | B34: 상면·POS 방향 | C34: 피부약·상처 보호 | D34: 건조·각화 외용약 | E34: Dry Skin Treatments | G34: 건조 외용약·보습 화장품 구분 | H34: 건조 피부 외용 연고 | I34: 각화·거친 피부 외용약 | J34: 외용 연고 큰 규격 | K34: 외용약 확장 여유 | L34: 5 | M34: 3 | N34: 0 | O34: 1 | P34: 1 | Q34: 기존 손 화장품을 G2-U-3으로 이동해 외용약 모듈로 정리. | R34: P-2F-02 / -02-1 | S34: 1700 | T34: =SUMIFS('02_선반315'!$P$7:$P$321,'02_선반315'!$B$7:$B$321,A34) -> 5 | U34: =SUMIFS('02_선반315'!$Q$7:$Q$321,'02_선반315'!$B$7:$B$321,A34) -> 6 | V34: PDF p3~4 (2026-08-11)
A35: G2-U-3 | B35: 상면·POS 방향 | C35: 더마·세정·선케어 | D35: 손·전신 보습 | E35: Hand & Body Moisture | F35: 케어리브 습윤형은 1~3단 연속 블록 | G35: 손·전신 보습 안내 | H35: 핸드크림 비교 | I35: 국소 보습·멀티밤 | J35: 전신 보습 로션 | K35: 손 세정 | L35: 5 | M35: 4 | N35: 0 | O35: 0 | P35: 1 | Q35: G2-U-2의 손 보습과 G5-U-3의 전신 보습을 통합. 의약품과 인접하되 화장품 표지를 별도 적용. | R35: P-2F-02 / -02-1 | S35: 1700 | T35: =SUMIFS('02_선반315'!$P$7:$P$321,'02_선반315'!$B$7:$B$321,A35) -> 6 | U35: =SUMIFS('02_선반315'!$Q$7:$Q$321,'02_선반315'!$B$7:$B$321,A35) -> 6 | V35: PDF p3~4 (2026-08-11)
A36: G3-D-1 | B36: 하면·입구 방향 | C36: 피부약·상처 보호 | D36: 기미·색소약 상담 | E36: 외용·경구약 별도 단 | G36: 색소·흉터의 차이 상담 | H36: 기미·색소 외용약 기본 | I36: 다른 규격·성분 외용약 | J36: 색소 경구 상담약 | K36: 외용약 추가 규격 여유 | L36: 5 | M36: 3 | N36: 0 | O36: 1 | P36: 1 | R36: P-2F-02 / -02-1 | S36: 1700 | T36: =SUMIFS('02_선반315'!$P$7:$P$321,'02_선반315'!$B$7:$B$321,A36) -> 5 | U36: =SUMIFS('02_선반315'!$Q$7:$Q$321,'02_선반315'!$B$7:$B$321,A36) -> 7 | V36: PDF p3~4 (2026-08-11)
A37: G3-D-2 | B37: 하면·입구 방향 | C37: 더마·세정·선케어 | D37: B 잡티·피부 톤 | E37: Spots & Tone | F37: 프로캄 멜라 1~2단 비교 블록 | G37: 톤 고민·현재 사용성분 안내 | H37: 프로캄·마미케어 톤 세럼 | I37: 닥터리쥬올 톤 세럼·크림 | J37: 다른 보습감의 톤 제형 | K37: 톤 고민 마스크 | L37: 5 | M37: 4 | N37: 0 | O37: 0 | P37: 1 | R37: P-2F-02 / -02-1 | S37: 1700 | T37: =SUMIFS('02_선반315'!$P$7:$P$321,'02_선반315'!$B$7:$B$321,A37) -> 8 | U37: =SUMIFS('02_선반315'!$Q$7:$Q$321,'02_선반315'!$B$7:$B$321,A37) -> 8 | V37: PDF p3~4 (2026-08-11)
A38: G3-D-3 | B38: 하면·입구 방향 | C38: 더마·세정·선케어 | D38: Sun Care | E38: 선케어 본진 | G38: 자외선차단 제형 안내 | H38: 세럼·에센스형 | I38: 크림형 비교 | J38: 톤업·보습형 | K38: 휴대 선스틱 | L38: 5 | M38: 4 | N38: 0 | O38: 0 | P38: 1 | R38: P-2F-02 / -02-1 | S38: 1700 | T38: =SUMIFS('02_선반315'!$P$7:$P$321,'02_선반315'!$B$7:$B$321,A38) -> 7 | U38: =SUMIFS('02_선반315'!$Q$7:$Q$321,'02_선반315'!$B$7:$B$321,A38) -> 7 | V38: PDF p3~4 (2026-08-11)
A39: G3-U-1 | B39: 상면·POS 방향 | C39: 일반약·여행·생활 | D39: Scalp & Hair | E39: 두피·모발 상담과 화장품 | G39: 두피 약·화장품 구분 | H39: 탈모 외용 의약품 | I39: 비듬·두피 상담약 | J39: 두피 세럼·토닉 화장품 | K39: 두피 세정 샴푸 | L39: 5 | M39: 4 | N39: 0 | O39: 0 | P39: 1 | R39: P-2F-02 / -02-1 | S39: 1700 | T39: =SUMIFS('02_선반315'!$P$7:$P$321,'02_선반315'!$B$7:$B$321,A39) -> 7 | U39: =SUMIFS('02_선반315'!$Q$7:$Q$321,'02_선반315'!$B$7:$B$321,A39) -> 7 | V39: PDF p3~4 (2026-08-11)
A40: G3-U-2 | B40: 상면·POS 방향 | C40: 일반약·여행·생활 | D40: Personal Care | E40: 개인 위생·민감한 상담 | G40: 여성 경구 상담약·낮은 포장 | H40: 여성 국소 상담약 | I40: 여성 청결 화장품 | J40: 생리 위생용품 | K40: 콘돔·자가 검사 | L40: 5 | M40: 5 | N40: 0 | O40: 0 | P40: 0 | R40: P-2F-02 / -02-1 | S40: 1700 | T40: =SUMIFS('02_선반315'!$P$7:$P$321,'02_선반315'!$B$7:$B$321,A40) -> 9 | U40: =SUMIFS('02_선반315'!$Q$7:$Q$321,'02_선반315'!$B$7:$B$321,A40) -> 9 | V40: PDF p3~4 (2026-08-11)
A41: G3-U-3 | B41: 상면·POS 방향 | C41: 일반약·여행·생활 | D41: Rest & Personal Care | E41: 숙면 관련 제품 구분 | G41: 수면·개인 상담 안내 | H41: 수면 상담 의약품 | I41: 수면 관련 식품·시험 | J41: 다른 섭취형태·시험 | K41: 치질·항문 불편 상담 | L41: 5 | M41: 2 | N41: 0 | O41: 2 | P41: 1 | Q41: 수면 의약품·식품은 선반 분리. S5는 옆 Personal Care와 연결되는 개별 상담 품목. | R41: P-2F-02 / -02-1 | S41: 1700 | T41: =SUMIFS('02_선반315'!$P$7:$P$321,'02_선반315'!$B$7:$B$321,A41) -> 7 | U41: =SUMIFS('02_선반315'!$Q$7:$Q$321,'02_선반315'!$B$7:$B$321,A41) -> 7 | V41: PDF p3~4 (2026-08-11)
A42: G4-D-1 | B42: 하면·입구 방향 | C42: 영양·건강 선물 | D42: Vitamin C & Inner Beauty | E42: C·이너뷰티 선택 | F42: 고려은단 C는 1~2단 선택형 연속 블록 | G42: 경구제품 분류 안내 | H42: 비타민C 의약품 후보 | I42: 비타민C 식품·건기식 후보 | J42: 글루타치온 함유 식품 | K42: 비타민C 다매 포장 | L42: 5 | M42: 4 | N42: 0 | O42: 0 | P42: 1 | R42: P-2F-02 / -02-1 | S42: 1700 | T42: =SUMIFS('02_선반315'!$P$7:$P$321,'02_선반315'!$B$7:$B$321,A42) -> 7 | U42: =SUMIFS('02_선반315'!$Q$7:$Q$321,'02_선반315'!$B$7:$B$321,A42) -> 8 | V42: PDF p3~4 (2026-08-11)
...

Sheet 02_선반315
A2: 315개 선반 · 증상·상품·페이싱·수용 검토
A3: S1 최상단 → S5 최하단 | 215단 상품 배정 · 60단 안내 · 40단 확장 여유 | 노란 확정란은 최종 실측·소매단위 확인 후 사용
A6: 선반 ID | B6: 모듈 | C6: 방향 | D6: 단 | E6: 주테마 | F6: 고민·증상 | G6: 운영 상품군 | H6: 권장 취급제품 | I6: 원본 공급코드 | J6: 대체 선택 방법 | K6: 운영 상태 | L6: 확정 상품명 | M6: 확정 공급코드 | N6: 진열·상담 기준 | O6: 자료 수준 | P6: 활성 SKU행 | Q6: 계획 F 합계 | R6: 적용 유효폭 | S6: 적용 깊이 | T6: 도면 개구높이 | U6: 상품높이 상한 | V6: 사용폭 합계 | W6: 수용 검토 | X6: 초기 SKU별 F | Y6: 후크 확인 | Z6: 개별 실측폭 | AA6: 개별 실측깊이 | AB6: 개별 실측개구
A7: W1/S1 | B7: W1 | C7: 상단 벽면 | D7: 1 | E7: 피부약·상처 보호 | F7: PDRN 분류·상담 안내 | G7: PDRN 일반의약품 / 창상피복재·MD 크림 | J7: 대체 후보는 전체 상품 시트에서 동일 상품군 필터 | K7: 안내 | N7: 높은 위치로 판매재고 대신 브랜드·제품 분류 안내. 무거운 선물 박스를 올리지 않음. | O7: PDF p5~6 (2026-08-11) + 원본 2526품목; 판매·마진 데이터 없음 | P7: =COUNTIFS('05_상품별배치367'!$B$7:$B$373,A7,'05_상품별배치367'!$K$7:$K$373,">0") -> 0 | Q7: =SUMIFS('05_상품별배치367'!$K$7:$K$373,'05_상품별배치367'!$B$7:$B$373,A7) -> 0 | R7: =IF(Z7="",'06_집기치수20'!N7,Z7) -> 865 | S7: =IF(AA7="",'06_집기치수20'!O7,AA7) -> 330 | T7: 460 | U7: =IF(AB7="",'06_집기치수20'!P7,AB7-'06_집기치수20'!I7) -> 440 | V7: =IF(Q7=0,"",IF(COUNTIFS('05_상품별배치367'!$B$7:$B$373,A7,'05_상품별배치367'!$T$7:$T$373,"입력 대기")>0,"",SUMIFS('05_상품별배치367'!$S$7:$S$373,'05_상품별배치367'!$B$7:$B$373,A7))) | W7: =IF(Q7=0,"미진열",IF(COUNTIFS('05_상품별배치367'!$B$7:$B$373,A7,'05_상품별배치367'!$T$7:$T$373,"치수 초과")>0,"치수 초과",IF(COUNTIFS('05_상품별배치367'!$B$7:$B$373,A7,'05_상품별배치367'!$T$7:$T$373,"입력 대기")>0,"치수 입력 대기",IF(V7>R7,"폭 합계 초과","도면/실측 범위 내·현장확인")))) -> 미진열 | Y7: 선반
A8: W1/S2 | B8: W1 | C8: 상단 벽면 | D8: 2 | E8: 피부약·상처 보호 | F8: PDRN 일반의약품 | G8: PDRN 일반의약품 | H8: 리쥬비넥스크림 | I8: pd0002364 | J8: 대체 후보는 전체 상품 시트에서 동일 상품군 필터 | K8: 오픈 진열 | N8: 상품명·규격은 원장 보존. 판매 단위·포장 치수·집기 실측 확인 후 배치 확정. | O8: PDF p5~6 (2026-08-11) + 원본 2526품목; 판매·마진 데이터 없음 | P8: =COUNTIFS('05_상품별배치367'!$B$7:$B$373,A8,'05_상품별배치367'!$K$7:$K$373,">0") -> 1 | Q8: =SUMIFS('05_상품별배치367'!$K$7:$K$373,'05_상품별배치367'!$B$7:$B$373,A8) -> 2 | R8: =IF(Z8="",'06_집기치수20'!N8,Z8) -> 865 | S8: =IF(AA8="",'06_집기치수20'!O8,AA8) -> 330 | T8: 290 | U8: =IF(AB8="",'06_집기치수20'!P8,AB8-'06_집기치수20'!I8) -> 270 | V8: =IF(Q8=0,"",IF(COUNTIFS('05_상품별배치367'!$B$7:$B$373,A8,'05_상품별배치367'!$T$7:$T$373,"입력 대기")>0,"",SUMIFS('05_상품별배치367'!$S$7:$S$373,'05_상품별배치367'!$B$7:$B$373,A8))) | W8: =IF(Q8=0,"미진열",IF(COUNTIFS('05_상품별배치367'!$B$7:$B$373,A8,'05_상품별배치367'!$T$7:$T$373,"치수 초과")>0,"치수 초과",IF(COUNTIFS('05_상품별배치367'!$B$7:$B$373,A8,'05_상품별배치367'!$T$7:$T$373,"입력 대기")>0,"치수 입력 대기",IF(V8>R8,"폭 합계 초과","도면/실측 범위 내·현장확인")))) -> 치수 입력 대기 | X8: pd0002364 2F | Y8: 선반
A9: W1/S3 | B9: W1 | C9: 상단 벽면 | D9: 3 | E9: 피부약·상처 보호 | F9: 가려움·피부염 외용약 | G9: 피부염·가려움 외용제 | H9: 리도프론크림 녹십자노바손크림 | I9: pd0000002 pd0001901 | J9: 대체 후보는 전체 상품 시트에서 동일 상품군 필터 | K9: 오픈 진열 | N9: 상품명·규격은 원장 보존. 판매 단위·포장 치수·집기 실측 확인 후 배치 확정. | O9: PDF p5~6 (2026-08-11) + 원본 2526품목; 판매·마진 데이터 없음 | P9: =COUNTIFS('05_상품별배치367'!$B$7:$B$373,A9,'05_상품별배치367'!$K$7:$K$373,">0") -> 2 | Q9: =SUMIFS('05_상품별배치367'!$K$7:$K$373,'05_상품별배치367'!$B$7:$B$373,A9) -> 2 | R9: =IF(Z9="",'06_집기치수20'!N9,Z9) -> 865 | S9: =IF(AA9="",'06_집기치수20'!O9,AA9) -> 330 | T9: 290 | U9: =IF(AB9="",'06_집기치수20'!P9,AB9-'06_집기치수20'!I9) -> 270 | V9: =IF(Q9=0,"",IF(COUNTIFS('05_상품별배치367'!$B$7:$B$373,A9,'05_상품별배치367'!$T$7:$T$373,"입력 대기")>0,"",SUMIFS('05_상품별배치367'!$S$7:$S$373,'05_상품별배치367'!$B$7:$B$373,A9))) | W9: =IF(Q9=0,"미진열",IF(COUNTIFS('05_상품별배치367'!$B$7:$B$373,A9,'05_상품별배치367'!$T$7:$T$373,"치수 초과")>0,"치수 초과",IF(COUNTIFS('05_상품별배치367'!$B$7:$B$373,A9,'05_상품별배치367'!$T$7:$T$373,"입력 대기")>0,"치수 입력 대기",IF(V9>R9,"폭 합계 초과","도면/실측 범위 내·현장확인")))) -> 치수 입력 대기 | X9: pd0000002 1F pd0001901 1F | Y9: 선반
A10: W1/S4 | B10: W1 | C10: 상단 벽면 | D10: 4 | E10: 피부약·상처 보호 | F10: 피부 상담약 확장 여유 | G10: 피부염·가려움 외용제 | J10: 대체 후보는 전체 상품 시트에서 동일 상품군 필터 | K10: 확장 여유 | N10: 상품명·규격은 원장 보존. 판매 단위·포장 치수·집기 실측 확인 후 배치 확정. | O10: PDF p5~6 (2026-08-11) + 원본 2526품목; 판매·마진 데이터 없음 | P10: =COUNTIFS('05_상품별배치367'!$B$7:$B$373,A10,'05_상품별배치367'!$K$7:$K$373,">0") -> 0 | Q10: =SUMIFS('05_상품별배치367'!$K$7:$K$373,'05_상품별배치367'!$B$7:$B$373,A10) -> 0 | R10: =IF(Z10="",'06_집기치수20'!N10,Z10) -> 865 | S10: =IF(AA10="",'06_집기치수20'!O10,AA10) -> 330 | T10: 290 | U10: =IF(AB10="",'06_집기치수20'!P10,AB10-'06_집기치수20'!I10) -> 270 | V10: =IF(Q10=0,"",IF(COUNTIFS('05_상품별배치367'!$B$7:$B$373,A10,'05_상품별배치367'!$T$7:$T$373,"입력 대기")>0,"",SUMIFS('05_상품별배치367'!$S$7:$S$373,'05_상품별배치367'!$B$7:$B$373,A10))) | W10: =IF(Q10=0,"미진열",IF(COUNTIFS('05_상품별배치367'!$B$7:$B$373,A10,'05_상품별배치367'!$T$7:$T$373,"치수 초과")>0,"치수 초과",IF(COUNTIFS('05_상품별배치367'!$B$7:$B$373,A10,'05_상품별배치367'!$T$7:$T$373,"입력 대기")>0,"치수 입력 대기",IF(V10>R10,"폭 합계 초과","도면/실측 범위 내·현장확인")))) -> 미진열 | Y10: 선반
A11: W1/S5 | B11: W1 | C11: 상단 벽면 | D11: 5 | E11: 피부약·상처 보호 | F11: MD 보호재·의료기기 분리 | G11: 창상피복재·MD 크림 | H11: 리쥬비엠디크림 비티테라 테라베리어크림 엠디(MD) | I11: pd0002328 pd0000602 | J11: 대체 후보는 전체 상품 시트에서 동일 상품군 필터 | K11: 오픈 진열 | N11: 상품명·규격은 원장 보존. 판매 단위·포장 치수·집기 실측 확인 후 배치 확정. | O11: PDF p5~6 (2026-08-11) + 원본 2526품목; 판매·마진 데이터 없음 | P11: =COUNTIFS('05_상품별배치367'!$B$7:$B$373,A11,'05_상품별배치367'!$K$7:$K$373,">0") -> 2 | Q11: =SUMIFS('05_상품별배치367'!$K$7:$K$373,'05_상품별배치367'!$B$7:$B$373,A11) -> 2 | R11: =IF(Z11="",'06_집기치수20'!N11,Z11) -> 865 | S11: =IF(AA11="",'06_집기치수20'!O11,AA11) -> 330 | T11: 330 | U11: =IF(AB11="",'06_집기치수20'!P11,AB11-'06_집기치수20'!I11) -> 310 | V11: =IF(Q11=0,"",IF(COUNTIFS('05_상품별배치367'!$B$7:$B$373,A11,'05_상품별배치367'!$T$7:$T$373,"입력 대기")>0,"",SUMIFS('05_상품별배치367'!$S$7:$S$373,'05_상품별배치367'!$B$7:$B$373,A11))) | W11: =IF(Q11=0,"미진열",IF(COUNTIFS('05_상품별배치367'!$B$7:$B$373,A11,'05_상품별배치367'!$T$7:$T$373,"치수 초과")>0,"치수 초과",IF(COUNTIFS('05_상품별배치367'!$B$7:$B$373,A11,'05_상품별배치367'!$T$7:$T$373,"입력 대기")>0,"치수 입력 대기",IF(V11>R11,"폭 합계 초과","도면/실측 범위 내·현장확인")))) -> 치수 입력 대기 | X11: pd0002328 1F pd0000602 1F | Y11: 선반
A12: W2/S1 | B12: W2 | C12: 상단 벽면 | D12: 1 | E12: 더마·세정·선케어 | F12: EGF 화장품 제형 안내 | G12: EGF 스킨케어 | J12: 대체 후보는 전체 상품 시트에서 동일 상품군 필터 | K12: 안내 | N12: 높은 위치로 판매재고 대신 브랜드·제품 분류 안내. 무거운 선물 박스를 올리지 않음. | O12: PDF p5~6 (2026-08-11) + 원본 2526품목; 판매·마진 데이터 없음 | P12: =COUNTIFS('05_상품별배치367'!$B$7:$B$373,A12,'05_상품별배치367'!$K$7:$K$373,">0") -> 0 | Q12: =SUMIFS('05_상품별배치367'!$K$7:$K$373,'05_상품별배치367'!$B$7:$B$373,A12) -> 0 | R12: =IF(Z12="",'06_집기치수20'!N7,Z12) -> 865 | S12: =IF(AA12="",'06_집기치수20'!O7,AA12) -> 330 | T12: 460 | U12: =IF(AB12="",'06_집기치수20'!P7,AB12-'06_집기치수20'!I7) -> 440 | V12: =IF(Q12=0,"",IF(COUNTIFS('05_상품별배치367'!$B$7:$B$373,A12,'05_상품별배치367'!$T$7:$T$373,"입력 대기")>0,"",SUMIFS('05_상품별배치367'!$S$7:$S$373,'05_상품별배치367'!$B$7:$B$373,A12))) | W12: =IF(Q12=0,"미진열",IF(COUNTIFS('05_상품별배치367'!$B$7:$B$373,A12,'05_상품별배치367'!$T$7:$T$373,"치수 초과")>0,"치수 초과",IF(COUNTIFS('05_상품별배치367'!$B$7:$B$373,A12,'05_상품별배치367'!$T$7:$T$373,"입력 대기")>0,"치수 입력 대기",IF(V12>R12,"폭 합계 초과","도면/실측 범위 내·현장확인")))) -> 미진열 | Y12: 선반
A13: W2/S2 | B13: W2 | C13: 상단 벽면 | D13: 2 | E13: 더마·세정·선케어 | F13: EGFx 앰플 비교 | G13: EGF 스킨케어 | H13: 이지에프엑스 포스트레이저 이지에프엑스 포스트엘써마 이지에프엑스 포스트스킨부스터 | I13: pd0002295 pd0002297 pd0002300 | J13: 대체 후보는 전체 상품 시트에서 동일 상품군 필터 | K13: 오픈 진열 | N13: 상품명·규격은 원장 보존. 판매 단위·포장 치수·집기 실측 확인 후 배치 확정. | O13: PDF p5~6 (2026-08-11) + 원본 2526품목; 판매·마진 데이터 없음 | P13: =COUNTIFS('05_상품별배치367'!$B$7:$B$373,A13,'05_상품별배치367'!$K$7:$K$373,">0") -> 3 | Q13: =SUMIFS('05_상품별배치367'!$K$7:$K$373,'05_상품별배치367'!$B$7:$B$373,A13) -> 3 | R13: =IF(Z13="",'06_집기치수20'!N8,Z13) -> 865 | S13: =IF(AA13="",'06_집기치수20'!O8,AA13) -> 330 | T13: 290 | U13: =IF(AB13="",'06_집기치수20'!P8,AB13-'06_집기치수20'!I8) -> 270 | V13: =IF(Q13=0,"",IF(COUNTIFS('05_상품별배치367'!$B$7:$B$373,A13,'05_상품별배치367'!$T$7:$T$373,"입력 대기")>0,"",SUMIFS('05_상품별배치367'!$S$7:$S$373,'05_상품별배치367'!$B$7:$B$373,A13))) | W13: =IF(Q13=0,"미진열",IF(COUNTIFS('05_상품별배치367'!$B$7:$B$373,A13,'05_상품별배치367'!$T$7:$T$373,"치수 초과")>0,"치수 초과",IF(COUNTIFS('05_상품별배치367'!$B$7:$B$373,A13,'05_상품별배치367'!$T$7:$T$373,"입력 대기")>0,"치수 입력 대기",IF(V13>R13,"폭 합계 초과","도면/실측 범위 내·현장확인")))) -> 치수 입력 대기 | X13: pd0002295 1F pd0002297 1F pd0002300 1F | Y13: 선반
A14: W2/S3 | B14: W2 | C14: 상단 벽면 | D14: 3 | E14: 더마·세정·선케어 | F14: 프로캄·이지듀 EGF 크림 | G14: EGF 스킨케어 | H14: 프로캄EGF 액티브 바이탈 크림 이지듀 3X 이지에프10 리페어크림 | I14: pd0002442 pd0002303 | J14: 대체 후보는 전체 상품 시트에서 동일 상품군 필터 | K14: 오픈 진열 | N14: 상품명·규격은 원장 보존. 판매 단위·포장 치수·집기 실측 확인 후 배치 확정. | O14: PDF p5~6 (2026-08-11) + 원본 2526품목; 판매·마진 데이터 없음 | P14: =COUNTIFS('05_상품별배치367'!$B$7:$B$373,A14,'05_상품별배치367'!$K$7:$K$373,">0") -> 2 | Q14: =SUMIFS('05_상품별배치367'!$K$7:$K$373,'05_상품별배치367'!$B$7:$B$373,A14) -> 3 | R14: =IF(Z14="",'06_집기치수20'!N9,Z14) -> 865 | S14: =IF(AA14="",'06_집기치수20'!O9,AA14) -> 330 | T14: 290 | U14: =IF(AB14="",'06_집기치수20'!P9,AB14-'06_집기치수20'!I9) -> 270 | V14: =IF(Q14=0,"",IF(COUNTIFS('05_상품별배치367'!$B$7:$B$373,A14,'05_상품별배치367'!$T$7:$T$373,"입력 대기")>0,"",SUMIFS('05_상품별배치367'!$S$7:$S$373,'05_상품별배치367'!$B$7:$B$373,A14))) | W14: =IF(Q14=0,"미진열",IF(COUNTIFS('05_상품별배치367'!$B$7:$B$373,A14,'05_상품별배치367'!$T$7:$T$373,"치수 초과")>0,"치수 초과",IF(COUNTIFS('05_상품별배치367'!$B$7:$B$373,A14,'05_상품별배치367'!$T$7:$T$373,"입력 대기")>0,"치수 입력 대기",IF(V14>R14,"폭 합계 초과","도면/실측 범위 내·현장확인")))) -> 치수 입력 대기 | X14: pd0002442 2F pd0002303 1F | Y14: 선반
A15: W2/S4 | B15: W2 | C15: 상단 벽면 | D15: 4 | E15: 더마·세정·선케어 | F15: EGF·PDRN 마스크 | G15: PDRN 스킨케어 | H15: 프로캄 EGF PDRN 액티브 시너지 마스크 | I15: pd0002372 | J15: 대체 후보는 전체 상품 시트에서 동일 상품군 필터 | K15: 오픈 진열 | N15: 상품명·규격은 원장 보존. 판매 단위·포장 치수·집기 실측 확인 후 배치 확정. | O15: PDF p5~6 (2026-08-11) + 원본 2526품목; 판매·마진 데이터 없음 | P15: =COUNTIFS('05_상품별배치367'!$B$7:$B$373,A15,'05_상품별배치367'!$K$7:$K$373,">0") -> 1 | Q15: =SUMIFS('05_상품별배치367'!$K$7:$K$373,'05_상품별배치367'!$B$7:$B$373,A15) -> 1 | R15: =IF(Z15="",'06_집기치수20'!N10,Z15) -> 865 | S15: =IF(AA15="",'06_집기치수20'!O10,AA15) -> 330 | T15: 290 | U15: =IF(AB15="",'06_집기치수20'!P10,AB15-'06_집기치수20'!I10) -> 270 | V15: =IF(Q15=0,"",IF(COUNTIFS('05_상품별배치367'!$B$7:$B$373,A15,'05_상품별배치367'!$T$7:$T$373,"입력 대기")>0,"",SUMIFS('05_상품별배치367'!$S$7:$S$373,'05_상품별배치367'!$B$7:$B$373,A15))) | W15: =IF(Q15=0,"미진열",IF(COUNTIFS('05_상품별배치367'!$B$7:$B$373,A15,'05_상품별배치367'!$T$7:$T$373,"치수 초과")>0,"치수 초과",IF(COUNTIFS('05_상품별배치367'!$B$7:$B$373,A15,'05_상품별배치367'!$T$7:$T$373,"입력 대기")>0,"치수 입력 대기",IF(V15>R15,"폭 합계 초과","도면/실측 범위 내·현장확인")))) -> 치수 입력 대기 | X15: pd0002372 1F | Y15: 선반
A16: W2/S5 | B16: W2 | C16: 상단 벽면 | D16: 5 | E16: 더마·세정·선케어 | F16: 프리미엄 추가 규격 여유 | G16: EGF 스킨케어 | J16: 대체 후보는 전체 상품 시트에서 동일 상품군 필터 | K16: 확장 여유 | N16: 상품명·규격은 원장 보존. 판매 단위·포장 치수·집기 실측 확인 후 배치 확정. | O16: PDF p5~6 (2026-08-11) + 원본 2526품목; 판매·마진 데이터 없음 | P16: =COUNTIFS('05_상품별배치367'!$B$7:$B$373,A16,'05_상품별배치367'!$K$7:$K$373,">0") -> 0 | Q16: =SUMIFS('05_상품별배치367'!$K$7:$K$373,'05_상품별배치367'!$B$7:$B$373,A16) -> 0 | R16: =IF(Z16="",'06_집기치수20'!N11,Z16) -> 865 | S16: =IF(AA16="",'06_집기치수20'!O11,AA16) -> 330 | T16: 330 | U16: =IF(AB16="",'06_집기치수20'!P11,AB16-'06_집기치수20'!I11) -> 310 | V16: =IF(Q16=0,"",IF(COUNTIFS('05_상품별배치367'!$B$7:$B$373,A16,'05_상품별배치367'!$T$7:$T$373,"입력 대기")>0,"",SUMIFS('05_상품별배치367'!$S$7:$S$373,'05_상품별배치367'!$B$7:$B$373,A16))) | W16: =IF(Q16=0,"미진열",IF(COUNTIFS('05_상품별배치367'!$B$7:$B$373,A16,'05_상품별배치367'!$T$7:$T$373,"치수 초과")>0,"치수 초과",IF(COUNTIFS('05_상품별배치367'!$B$7:$B$373,A16,'05_상품별배치367'!$T$7:$T$373,"입력 대기")>0,"치수 입력 대기",IF(V16>R16,"폭 합계 초과","도면/실측 범위 내·현장확인")))) -> 미진열 | Y16: 선반
A17: W3/S1 | B17: W3 | C17: 상단 벽면 | D17: 1 | E17: 추천·상담 안내 | F17: 환절기 보습 테마 | G17: 안내·교체 여유 | J17: 대체 후보는 전체 상품 시트에서 동일 상품군 필터 | K17: 안내 | N17: 높은 위치로 판매재고 대신 브랜드·제품 분류 안내. 무거운 선물 박스를 올리지 않음. | O17: PDF p5~6 (2026-08-11) + 원본 2526품목; 판매·마진 데이터 없음 | P17: =COUNTIFS('05_상품별배치367'!$B$7:$B$373,A17,'05_상품별배치367'!$K$7:$K$373,">0") -> 0 | Q17: =SUMIFS('05_상품별배치367'!$K$7:$K$373,'05_상품별배치367'!$B$7:$B$373,A17) -> 0 | R17: =IF(Z17="",'06_집기치수20'!N7,Z17) -> 865 | S17: =IF(AA17="",'06_집기치수20'!O7,AA17) -> 330 | T17: 460 | U17: =IF(AB17="",'06_집기치수20'!P7,AB17-'06_집기치수20'!I7) -> 440 | V17: =IF(Q17=0,"",IF(COUNTIFS('05_상품별배치367'!$B$7:$B$373,A17,'05_상품별배치367'!$T$7:$T$373,"입력 대기")>0,"",SUMIFS('05_상품별배치367'!$S$7:$S$373,'05_상품별배치367'!$B$7:$B$373,A17))) | W17: =IF(Q17=0,"미진열",IF(COUNTIFS('05_상품별배치367'!$B$7:$B$373,A17,'05_상품별배치367'!$T$7:$T$373,"치수 초과")>0,"치수 초과",IF(COUNTIFS('05_상품별배치367'!$B$7:$B$373,A17,'05_상품별배치367'!$T$7:$T$373,"입력 대기")>0,"치수 입력 대기",IF(V17>R17,"폭 합계 초과","도면/실측 범위 내·현장확인")))) -> 미진열 | Y17: 선반
A18: W3/S2 | B18: W3 | C18: 상단 벽면 | D18: 2 | E18: 추천·상담 안내 | F18: 진정 크림 테마 | G18: 진정 스킨케어 | H18: 프로캄 후시메디 리페어 크림S | I18: pd0002461 | J18: 대체 후보는 전체 상품 시트에서 동일 상품군 필터 | K18: 테마 진열 | N18: 상품명·규격은 원장 보존. 판매 단위·포장 치수·집기 실측 확인 후 배치 확정. | O18: PDF p5~6 (2026-08-11) + 원본 2526품목; 판매·마진 데이터 없음 | P18: =COUNTIFS('05_상품별배치367'!$B$7:$B$373,A18,'05_상품별배치367'!$K$7:$K$373,">0") -> 1 | Q18: =SUMIFS('05_상품별배치367'!$K$7:$K$373,'05_상품별배치367'!$B$7:$B$373,A18) -> 1 | R18: =IF(Z18="",'06_집기치수20'!N8,Z18) -> 865 | S18: =IF(AA18="",'06_집기치수20'!O8,AA18) -> 330 | T18: 290 | U18: =IF(AB18="",'06_집기치수20'!P8,AB18-'06_집기치수20'!I8) -> 270 | V18: =IF(Q18=0,"",IF(COUNTIFS('05_상품별배치367'!$B$7:$B$373,A18,'05_상품별배치367'!$T$7:$T$373,"입력 대기")>0,"",SUMIFS('05_상품별배치367'!$S$7:$S$373,'05_상품별배치367'!$B$7:$B$373,A18))) | W18: =IF(Q18=0,"미진열",IF(COUNTIFS('05_상품별배치367'!$B$7:$B$373,A18,'05_상품별배치367'!$T$7:$T$373,"치수 초과")>0,"치수 초과",IF(COUNTIFS('05_상품별배치367'!$B$7:$B$373,A18,'05_상품별배치367'!$T$7:$T$373,"입력 대기")>0,"치수 입력 대기",IF(V18>R18,"폭 합계 초과","도면/실측 범위 내·현장확인")))) -> 치수 입력 대기 | X18: pd0002461 1F | Y18: 선반
A19: W3/S3 | B19: W3 | C19: 상단 벽면 | D19: 3 | E19: 추천·상담 안내 | F19: 장벽 세럼 테마 | G19: 장벽·보습 스킨케어 | H19: 톰 PPM 트리플 시너지 베리어 세럼 | I19: pd0002415 | J19: 대체 후보는 전체 상품 시트에서 동일 상품군 필터 | K19: 테마 진열 | N19: 상품명·규격은 원장 보존. 판매 단위·포장 치수·집기 실측 확인 후 배치 확정. | O19: PDF p5~6 (2026-08-11) + 원본 2526품목; 판매·마진 데이터 없음 | P19: =COUNTIFS('05_상품별배치367'!$B$7:$B$373,A19,'05_상품별배치367'!$K$7:$K$373,">0") -> 1 | Q19: =SUMIFS('05_상품별배치367'!$K$7:$K$373,'05_상품별배치367'!$B$7:$B$373,A19) -> 1 | R19: =IF(Z19="",'06_집기치수20'!N9,Z19) -> 865 | S19: =IF(AA19="",'06_집기치수20'!O9,AA19) -> 330 | T19: 290 | U19: =IF(AB19="",'06_집기치수20'!P9,AB19-'06_집기치수20'!I9) -> 270 | V19: =IF(Q19=0,"",IF(COUNTIFS('05_상품별배치367'!$B$7:$B$373,A19,'05_상품별배치367'!$T$7:$T$373,"입력 대기")>0,"",SUMIFS('05_상품별배치367'!$S$7:$S$373,'05_상품별배치367'!$B$7:$B$373,A19))) | W19: =IF(Q19=0,"미진열",IF(COUNTIFS('05_상품별배치367'!$B$7:$B$373,A19,'05_상품별배치367'!$T$7:$T$373,"치수 초과")>0,"치수 초과",IF(COUNTIFS('05_상품별배치367'!$B$7:$B$373,A19,'05_상품별배치367'!$T$7:$T$373,"입력 대기")>0,"치수 입력 대기",IF(V19>R19,"폭 합계 초과","도면/실측 범위 내·현장확인")))) -> 치수 입력 대기 | X19: pd0002415 1F | Y19: 선반
A20: W3/S4 | B20: W3 | C20: 상단 벽면 | D20: 4 | E20: 추천·상담 안내 | F20: 립 보습 연결 | G20: 립 보습 화장품 | H20: 리쥬올 PDRN 립세럼 | I20: pd0002336 | J20: 대체 후보는 전체 상품 시트에서 동일 상품군 필터 | K20: 테마 진열 | N20: 상품명·규격은 원장 보존. 판매 단위·포장 치수·집기 실측 확인 후 배치 확정. | O20: PDF p5~6 (2026-08-11) + 원본 2526품목; 판매·마진 데이터 없음 | P20: =COUNTIFS('05_상품별배치367'!$B$7:$B$373,A20,'05_상품별배치367'!$K$7:$K$373,">0") -> 1 | Q20: =SUMIFS('05_상품별배치367'!$K$7:$K$373,'05_상품별배치367'!$B$7:$B$373,A20) -> 1 | R20: =IF(Z20="",'06_집기치수20'!N10,Z20) -> 865 | S20: =IF(AA20="",'06_집기치수20'!O10,AA20) -> 330 | T20: 290 | U20: =IF(AB20="",'06_집기치수20'!P10,AB20-'06_집기치수20'!I10) -> 270 | V20: =IF(Q20=0,"",IF(COUNTIFS('05_상품별배치367'!$B$7:$B$373,A20,'05_상품별배치367'!$T$7:$T$373,"입력 대기")>0,"",SUMIFS('05_상품별배치367'!$S$7:$S$373,'05_상품별배치367'!$B$7:$B$373,A20))) | W20: =IF(Q20=0,"미진열",IF(COUNTIFS('05_상품별배치367'!$B$7:$B$373,A20,'05_상품별배치367'!$T$7:$T$373,"치수 초과")>0,"치수 초과",IF(COUNTIFS('05_상품별배치367'!$B$7:$B$373,A20,'05_상품별배치367'!$T$7:$T$373,"입력 대기")>0,"치수 입력 대기",IF(V20>R20,"폭 합계 초과","도면/실측 범위 내·현장확인")))) -> 치수 입력 대기 | X20: pd0002336 1F | Y20: 선반
A21: W3/S5 | B21: W3 | C21: 상단 벽면 | D21: 5 | E21: 추천·상담 안내 | F21: 다음 테마 교체 여유 | G21: 안내·교체 여유 | J21: 대체 후보는 전체 상품 시트에서 동일 상품군 필터 | K21: 확장 여유 | N21: 상품명·규격은 원장 보존. 판매 단위·포장 치수·집기 실측 확인 후 배치 확정. | O21: PDF p5~6 (2026-08-11) + 원본 2526품목; 판매·마진 데이터 없음 | P21: =COUNTIFS('05_상품별배치367'!$B$7:$B$373,A21,'05_상품별배치367'!$K$7:$K$373,">0") -> 0 | Q21: =SUMIFS('05_상품별배치367'!$K$7:$K$373,'05_상품별배치367'!$B$7:$B$373,A21) -> 0 | R21: =IF(Z21="",'06_집기치수20'!N11,Z21) -> 865 | S21: =IF(AA21="",'06_집기치수20'!O11,AA21) -> 330 | T21: 330 | U21: =IF(AB21="",'06_집기치수20'!P11,AB21-'06_집기치수20'!I11) -> 310 | V21: =IF(Q21=0,"",IF(COUNTIFS('05_상품별배치367'!$B$7:$B$373,A21,'05_상품별배치367'!$T$7:$T$373,"입력 대기")>0,"",SUMIFS('05_상품별배치367'!$S$7:$S$373,'05_상품별배치367'!$B$7:$B$373,A21))) | W21: =IF(Q21=0,"미진열",IF(COUNTIFS('05_상품별배치367'!$B$7:$B$373,A21,'05_상품별배치367'!$T$7:$T$373,"치수 초과")>0,"치수 초과",IF(COUNTIFS('05_상품별배치367'!$B$7:$B$373,A21,'05_상품별배치367'!$T$7:$T$373,"입력 대기")>0,"치수 입력 대기",IF(V21>R21,"폭 합계 초과","도면/실측 범위 내·현장확인")))) -> 미진열 | Y21: 선반
A22: W4/S1 | B22: W4 | C22: 상단 벽면 | D22: 1 | E22: 영양·건강 선물 | F22: 경구 영양 상담 안내 | G22: 비타민B 경구제품 | J22: 대체 후보는 전체 상품 시트에서 동일 상품군 필터 | K22: 안내 | N22: 높은 위치로 판매재고 대신 브랜드·제품 분류 안내. 무거운 선물 박스를 올리지 않음. | O22: PDF p5~6 (2026-08-11) + 원본 2526품목; 판매·마진 데이터 없음 | P22: =COUNTIFS('05_상품별배치367'!$B$7:$B$373,A22,'05_상품별배치367'!$K$7:$K$373,">0") -> 0 | Q22: =SUMIFS('05_상품별배치367'!$K$7:$K$373,'05_상품별배치367'!$B$7:$B$373,A22) -> 0 | R22: =IF(Z22="",'06_집기치수20'!N7,Z22) -> 865 | S22: =IF(AA22="",'06_집기치수20'!O7,AA22) -> 330 | T22: 460 | U22: =IF(AB22="",'06_집기치수20'!P7,AB22-'06_집기치수20'!I7) -> 440 | V22: =IF(Q22=0,"",IF(COUNTIFS('05_상품별배치367'!$B$7:$B$373,A22,'05_상품별배치367'!$T$7:$T$373,"입력 대기")>0,"",SUMIFS('05_상품별배치367'!$S$7:$S$373,'05_상품별배치367'!$B$7:$B$373,A22))) | W22: =IF(Q22=0,"미진열",IF(COUNTIFS('05_상품별배치367'!$B$7:$B$373,A22,'05_상품별배치367'!$T$7:$T$373,"치수 초과")>0,"치수 초과",IF(COUNTIFS('05_상품별배치367'!$B$7:$B$373,A22,'05_상품별배치367'!$T$7:$T$373,"입력 대기")>0,"치수 입력 대기",IF(V22>R22,"폭 합계 초과","도면/실측 범위 내·현장확인")))) -> 미진열 | Y22: 선반
A23: W4/S2 | B23: W4 | C23: 상단 벽면 | D23: 2 | E23: 영양·건강 선물 | F23: 비타민B 의약품 | G23: 비타민B 경구제품 | H23: 비맥스메타비 임팩타민 시그니처정 비맥스메타정 | I23: pd0001998 pd0002406 pd0002002 | J23: 대체 후보는 전체 상품 시트에서 동일 상품군 필터 | K23: 오픈 진열 | N23: 상품명·규격은 원장 보존. 판매 단위·포장 치수·집기 실측 확인 후 배치 확정. | O23: PDF p5~6 (2026-08-11) + 원본 2526품목; 판매·마진 데이터 없음 | P23: =COUNTIFS('05_상품별배치367'!$B$7:$B$373,A23,'05_상품별배치367'!$K$7:$K$373,">0") -> 3 | Q23: =SUMIFS('05_상품별배치367'!$K$7:$K$373,'05_상품별배치367'!$B$7:$B$373,A23) -> 3 | R23: =IF(Z23="",'06_집기치수20'!N8,Z23) -> 865 | S23: =IF(AA23="",'06_집기치수20'!O8,AA23) -> 330 | T23: 290 | U23: =IF(AB23="",'06_집기치수20'!P8,AB23-'06_집기치수20'!I8) -> 270 | V23: =IF(Q23=0,"",IF(COUNTIFS('05_상품별배치367'!$B$7:$B$373,A23,'05_상품별배치367'!$T$7:$T$373,"입력 대기")>0,"",SUMIFS('05_상품별배치367'!$S$7:$S$373,'05_상품별배치367'!$B$7:$B$373,A23))) | W23: =IF(Q23=0,"미진열",IF(COUNTIFS('05_상품별배치367'!$B$7:$B$373,A23,'05_상품별배치367'!$T$7:$T$373,"치수 초과")>0,"치수 초과",IF(COUNTIFS('05_상품별배치367'!$B$7:$B$373,A23,'05_상품별배치367'!$T$7:$T$373,"입력 대기")>0,"치수 입력 대기",IF(V23>R23,"폭 합계 초과","도면/실측 범위 내·현장확인")))) -> 치수 입력 대기 | X23: pd0001998 1F pd0002406 1F pd0002002 1F | Y23: 선반
A24: W4/S3 | B24: W4 | C24: 상단 벽면 | D24: 3 | E24: 영양·건강 선물 | F24: 마그네슘 경구제품 | G24: 마그네슘 경구제품 | H24: 마그비스피드더블액션 마그콤 | I24: pd0002410 pd0000052 | J24: 대체 후보는 전체 상품 시트에서 동일 상품군 필터 | K24: 오픈 진열 | N24: 상품명·규격은 원장 보존. 판매 단위·포장 치수·집기 실측 확인 후 배치 확정. | O24: PDF p5~6 (2026-08-11) + 원본 2526품목; 판매·마진 데이터 없음 | P24: =COUNTIFS('05_상품별배치367'!$B$7:$B$373,A24,'05_상품별배치367'!$K$7:$K$373,">0") -> 2 | Q24: =SUMIFS('05_상품별배치367'!$K$7:$K$373,'05_상품별배치367'!$B$7:$B$373,A24) -> 2 | R24: =IF(Z24="",'06_집기치수20'!N9,Z24) -> 865 | S24: =IF(AA24="",'06_집기치수20'!O9,AA24) -> 330 | T24: 290 | U24: =IF(AB24="",'06_집기치수20'!P9,AB24-'06_집기치수20'!I9) -> 270 | V24: =IF(Q24=0,"",IF(COUNTIFS('05_상품별배치367'!$B$7:$B$373,A24,'05_상품별배치367'!$T$7:$T$373,"입력 대기")>0,"",SUMIFS('05_상품별배치367'!$S$7:$S$373,'05_상품별배치367'!$B$7:$B$373,A24))) | W24: =IF(Q24=0,"미진열",IF(COUNTIFS('05_상품별배치367'!$B$7:$B$373,A24,'05_상품별배치367'!$T$7:$T$373,"치수 초과")>0,"치수 초과",IF(COUNTIFS('05_상품별배치367'!$B$7:$B$373,A24,'05_상품별배치367'!$T$7:$T$373,"입력 대기")>0,"치수 입력 대기",IF(V24>R24,"폭 합계 초과","도면/실측 범위 내·현장확인")))) -> 치수 입력 대기 | X24: pd0002410 1F pd0000052 1F | Y24: 선반
A25: W4/S4 | B25: W4 | C25: 상단 벽면 | D25: 4 | E25: 영양·건강 선물 | F25: 글루타치온 의약품 | G25: 글루타치온 경구 의약품 | H25: 에바치온캡슐 | I25: pd0001907 | J25: 대체 후보는 전체 상품 시트에서 동일 상품군 필터 | K25: 오픈 진열 | N25: 상품명·규격은 원장 보존. 판매 단위·포장 치수·집기 실측 확인 후 배치 확정. | O25: PDF p5~6 (2026-08-11) + 원본 2526품목; 판매·마진 데이터 없음 | P25: =COUNTIFS('05_상품별배치367'!$B$7:$B$373,A25,'05_상품별배치367'!$K$7:$K$373,">0") -> 1 | Q25: =SUMIFS('05_상품별배치367'!$K$7:$K$373,'05_상품별배치367'!$B$7:$B$373,A25) -> 1 | R25: =IF(Z25="",'06_집기치수20'!N10,Z25) -> 865 | S25: =IF(AA25="",'06_집기치수20'!O10,AA25) -> 330 | T25: 290 | U25: =IF(AB25="",'06_집기치수20'!P10,AB25-'06_집기치수20'!I10) -> 270 | V25: =IF(Q25=0,"",IF(COUNTIFS('05_상품별배치367'!$B$7:$B$373,A25,'05_상품별배치367'!$T$7:$T$373,"입력 대기")>0,"",SUMIFS('05_상품별배치367'!$S$7:$S$373,'05_상품별배치367'!$B$7:$B$373,A25))) | W25: =IF(Q25=0,"미진열",IF(COUNTIFS('05_상품별배치367'!$B$7:$B$373,A25,'05_상품별배치367'!$T$7:$T$373,"치수 초과")>0,"치수 초과",IF(COUNTIFS('05_상품별배치367'!$B$7:$B$373,A25,'05_상품별배치367'!$T$7:$T$373,"입력 대기")>0,"치수 입력 대기",IF(V25>R25,"폭 합계 초과","도면/실측 범위 내·현장확인")))) -> 치수 입력 대기 | X25: pd0001907 1F | Y25: 선반
A26: W4/S5 | B26: W4 | C26: 상단 벽면 | D26: 5 | E26: 영양·건강 선물 | F26: 피로·간·한방 상담약 | G26: 자양강장·한방 상담약 / 간 관련 상담약 | H26: 글루콤액 한풍 경옥고 우루사정100mg 헤파토스시럽 | I26: pd0000013 pd0002052 pd0002489 pd0002488 | J26: 대체 후보는 전체 상품 시트에서 동일 상품군 필터 | K26: 오픈 진열 | N26: 상품명·규격은 원장 보존. 판매 단위·포장 치수·집기 실측 확인 후 배치 확정. | O26: PDF p5~6 (2026-08-11) + 원본 2526품목; 판매·마진 데이터 없음 | P26: =COUNTIFS('05_상품별배치367'!$B$7:$B$373,A26,'05_상품별배치367'!$K$7:$K$373,">0") -> 4 | Q26: =SUMIFS('05_상품별배치367'!$K$7:$K$373,'05_상품별배치367'!$B$7:$B$373,A26) -> 4 | R26: =IF(Z26="",'06_집기치수20'!N11,Z26) -> 865 | S26: =IF(AA26="",'06_집기치수20'!O11,AA26) -> 330 | T26: 330 | U26: =IF(AB26="",'06_집기치수20'!P11,AB26-'06_집기치수20'!I11) -> 310 | V26: =IF(Q26=0,"",IF(COUNTIFS('05_상품별배치367'!$B$7:$B$373,A26,'05_상품별배치367'!$T$7:$T$373,"입력 대기")>0,"",SUMIFS('05_상품별배치367'!$S$7:$S$373,'05_상품별배치367'!$B$7:$B$373,A26))) | W26: =IF(Q26=0,"미진열",IF(COUNTIFS('05_상품별배치367'!$B$7:$B$373,A26,'05_상품별배치367'!$T$7:$T$373,"치수 초과")>0,"치수 초과",IF(COUNTIFS('05_상품별배치367'!$B$7:$B$373,A26,'05_상품별배치367'!$T$7:$T$373,"입력 대기")>0,"치수 입력 대기",IF(V26>R26,"폭 합계 초과","도면/실측 범위 내·현장확인")))) -> 치수 입력 대기 | X26: pd0000013 1F pd0002052 1F pd0002489 1F pd0002488 1F | Y26: 선반
A27: W5/S1 | B27: W5 | C27: 상단 벽면 | D27: 1 | E27: 영양·건강 선물 | F27: 정규 선물 구성 안내 | G27: 홍삼 제품 | J27: 대체 후보는 전체 상품 시트에서 동일 상품군 필터 | K27: 안내 | N27: 높은 위치로 판매재고 대신 브랜드·제품 분류 안내. 무거운 선물 박스를 올리지 않음. | O27: PDF p5~6 (2026-08-11) + 원본 2526품목; 판매·마진 데이터 없음 | P27: =COUNTIFS('05_상품별배치367'!$B$7:$B$373,A27,'05_상품별배치367'!$K$7:$K$373,">0") -> 0 | Q27: =SUMIFS('05_상품별배치367'!$K$7:$K$373,'05_상품별배치367'!$B$7:$B$373,A27) -> 0 | R27: =IF(Z27="",'06_집기치수20'!N7,Z27) -> 865 | S27: =IF(AA27="",'06_집기치수20'!O7,AA27) -> 330 | T27: 460 | U27: =IF(AB27="",'06_집기치수20'!P7,AB27-'06_집기치수20'!I7) -> 440 | V27: =IF(Q27=0,"",IF(COUNTIFS('05_상품별배치367'!$B$7:$B$373,A27,'05_상품별배치367'!$T$7:$T$373,"입력 대기")>0,"",SUMIFS('05_상품별배치367'!$S$7:$S$373,'05_상품별배치367'!$B$7:$B$373,A27))) | W27: =IF(Q27=0,"미진열",IF(COUNTIFS('05_상품별배치367'!$B$7:$B$373,A27,'05_상품별배치367'!$T$7:$T$373,"치수 초과")>0,"치수 초과",IF(COUNTIFS('05_상품별배치367'!$B$7:$B$373,A27,'05_상품별배치367'!$T$7:$T$373,"입력 대기")>0,"치수 입력 대기",IF(V27>R27,"폭 합계 초과","도면/실측 범위 내·현장확인")))) -> 미진열 | Y27: 선반
A28: W5/S2 | B28: W5 | C28: 상단 벽면 | D28: 2 | E28: 영양·건강 선물 | F28: 멀티비타민 정규 세트 | G28: 멀티비타민·미네랄 | H28: 한미 엔플 프리미엄 멀티비타민 이뮨삿 7병 비타블로썸 멀티비타민 이뮨 부스터 | I28: pd0002216 pd0002398 | J28: 대체 후보는 전체 상품 시트에서 동일 상품군 필터 | K28: 오픈 진열 | N28: 상품명·규격은 원장 보존. 판매 단위·포장 치수·집기 실측 확인 후 배치 확정. | O28: PDF p5~6 (2026-08-11) + 원본 2526품목; 판매·마진 데이터 없음 | P28: =COUNTIFS('05_상품별배치367'!$B$7:$B$373,A28,'05_상품별배치367'!$K$7:$K$373,">0") -> 2 | Q28: =SUMIFS('05_상품별배치367'!$K$7:$K$373,'05_상품별배치367'!$B$7:$B$373,A28) -> 2 | R28: =IF(Z28="",'06_집기치수20'!N8,Z28) -> 865 | S28: =IF(AA28="",'06_집기치수20'!O8,AA28) -> 330 | T28: 290 | U28: =IF(AB28="",'06_집기치수20'!P8,AB28-'06_집기치수20'!I8) -> 270 | V28: =IF(Q28=0,"",IF(COUNTIFS('05_상품별배치367'!$B$7:$B$373,A28,'05_상품별배치367'!$T$7:$T$373,"입력 대기")>0,"",SUMIFS('05_상품별배치367'!$S$7:$S$373,'05_상품별배치367'!$B$7:$B$373,A28))) | W28: =IF(Q28=0,"미진열",IF(COUNTIFS('05_상품별배치367'!$B$7:$B$373,A28,'05_상품별배치367'!$T$7:$T$373,"치수 초과")>0,"치수 초과",IF(COUNTIFS('05_상품별배치367'!$B$7:$B$373,A28,'05_상품별배치367'!$T$7:$T$373,"입력 대기")>0,"치수 입력 대기",IF(V28>R28,"폭 합계 초과","도면/실측 범위 내·현장확인")))) -> 치수 입력 대기 | X28: pd0002216 1F pd0002398 1F | Y28: 선반
A29: W5/S3 | B29: W5 | C29: 상단 벽면 | D29: 3 | E29: 영양·건강 선물 | F29: 홍삼 30포 비교 | G29: 홍삼 제품 | H29: 정원삼 6년근 고려홍삼정365스틱 정원삼 6년근 발효홍삼 농축액스틱 | I29: pd0002059 pd0002055 | J29: 대체 후보는 전체 상품 시트에서 동일 상품군 필터 | K29: 오픈 진열 | N29: 상품명·규격은 원장 보존. 판매 단위·포장 치수·집기 실측 확인 후 배치 확정. | O29: PDF p5~6 (2026-08-11) + 원본 2526품목; 판매·마진 데이터 없음 | P29: =COUNTIFS('05_상품별배치367'!$B$7:$B$373,A29,'05_상품별배치367'!$K$7:$K$373,">0") -> 2 | Q29: =SUMIFS('05_상품별배치367'!$K$7:$K$373,'05_상품별배치367'!$B$7:$B$373,A29) -> 2 | R29: =IF(Z29="",'06_집기치수20'!N9,Z29) -> 865 | S29: =IF(AA29="",'06_집기치수20'!O9,AA29) -> 330 | T29: 290 | U29: =IF(AB29="",'06_집기치수20'!P9,AB29-'06_집기치수20'!I9) -> 270 | V29: =IF(Q29=0,"",IF(COUNTIFS('05_상품별배치367'!$B$7:$B$373,A29,'05_상품별배치367'!$T$7:$T$373,"입력 대기")>0,"",SUMIFS('05_상품별배치367'!$S$7:$S$373,'05_상품별배치367'!$B$7:$B$373,A29))) | W29: =IF(Q29=0,"미진열",IF(COUNTIFS('05_상품별배치367'!$B$7:$B$373,A29,'05_상품별배치367'!$T$7:$T$373,"치수 초과")>0,"치수 초과",IF(COUNTIFS('05_상품별배치367'!$B$7:$B$373,A29,'05_상품별배치367'!$T$7:$T$373,"입력 대기")>0,"치수 입력 대기",IF(V29>R29,"폭 합계 초과","도면/실측 범위 내·현장확인")))) -> 치수 입력 대기 | X29: pd0002059 1F pd0002055 1F | Y29: 선반
A30: W5/S4 | B30: W5 | C30: 상단 벽면 | D30: 4 | E30: 영양·건강 선물 | F30: 콜라겐·홍삼 젤리 | G30: 콜라겐·이너뷰티 / 홍삼 제품 | H30: 에버콜라겐 블랙 정원삼 6년근 고려홍삼정 로얄젤리스틱 | I30: pd0000061 pd0002053 | J30: 대체 후보는 전체 상품 시트에서 동일 상품군 필터 | K30: 오픈 진열 | N30: 상품명·규격은 원장 보존. 판매 단위·포장 치수·집기 실측 확인 후 배치 확정. | O30: PDF p5~6 (2026-08-11) + 원본 2526품목; 판매·마진 데이터 없음 | P30: =COUNTIFS('05_상품별배치367'!$B$7:$B$373,A30,'05_상품별배치367'!$K$7:$K$373,">0") -> 2 | Q30: =SUMIFS('05_상품별배치367'!$K$7:$K$373,'05_상품별배치367'!$B$7:$B$373,A30) -> 2 | R30: =IF(Z30="",'06_집기치수20'!N10,Z30) -> 865 | S30: =IF(AA30="",'06_집기치수20'!O10,AA30) -> 330 | T30: 290 | U30: =IF(AB30="",'06_집기치수20'!P10,AB30-'06_집기치수20'!I10) -> 270 | V30: =IF(Q30=0,"",IF(COUNTIFS('05_상품별배치367'!$B$7:$B$373,A30,'05_상품별배치367'!$T$7:$T$373,"입력 대기")>0,"",SUMIFS('05_상품별배치367'!$S$7:$S$373,'05_상품별배치367'!$B$7:$B$373,A30))) | W30: =IF(Q30=0,"미진열",IF(COUNTIFS('05_상품별배치367'!$B$7:$B$373,A30,'05_상품별배치367'!$T$7:$T$373,"치수 초과")>0,"치수 초과",IF(COUNTIFS('05_상품별배치367'!$B$7:$B$373,A30,'05_상품별배치367'!$T$7:$T$373,"입력 대기")>0,"치수 입력 대기",IF(V30>R30,"폭 합계 초과","도면/실측 범위 내·현장확인")))) -> 치수 입력 대기 | X30: pd0000061 1F pd0002053 1F | Y30: 선반
A31: W5/S5 | B31: W5 | C31: 상단 벽면 | D31: 5 | E31: 영양·건강 선물 | F31: 다매 홍삼·절편 | G31: 홍삼 제품 | H31: 정원삼 6년근 고려홍삼정365스틱 정원삼 고려홍삼절편 365 | I31: pd0002057 pd0002085 | J31: 대체 후보는 전체 상품 시트에서 동일 상품군 필터 | K31: 오픈 진열 | N31: 상품명·규격은 원장 보존. 판매 단위·포장 치수·집기 실측 확인 후 배치 확정. | O31: PDF p5~6 (2026-08-11) + 원본 2526품목; 판매·마진 데이터 없음 | P31: =COUNTIFS('05_상품별배치367'!$B$7:$B$373,A31,'05_상품별배치367'!$K$7:$K$373,">0") -> 2 | Q31: =SUMIFS('05_상품별배치367'!$K$7:$K$373,'05_상품별배치367'!$B$7:$B$373,A31) -> 2 | R31: =IF(Z31="",'06_집기치수20'!N11,Z31) -> 865 | S31: =IF(AA31="",'06_집기치수20'!O11,AA31) -> 330 | T31: 330 | U31: =IF(AB31="",'06_집기치수20'!P11,AB31-'06_집기치수20'!I11) -> 310 | V31: =IF(Q31=0,"",IF(COUNTIFS('05_상품별배치367'!$B$7:$B$373,A31,'05_상품별배치367'!$T$7:$T$373,"입력 대기")>0,"",SUMIFS('05_상품별배치367'!$S$7:$S$373,'05_상품별배치367'!$B$7:$B$373,A31))) | W31: =IF(Q31=0,"미진열",IF(COUNTIFS('05_상품별배치367'!$B$7:$B$373,A31,'05_상품별배치367'!$T$7:$T$373,"치수 초과")>0,"치수 초과",IF(COUNTIFS('05_상품별배치367'!$B$7:$B$373,A31,'05_상품별배치367'!$T$7:$T$373,"입력 대기")>0,"치수 입력 대기",IF(V31>R31,"폭 합계 초과","도면/실측 범위 내·현장확인")))) -> 치수 입력 대기 | X31: pd0002057 1F pd0002085 1F | Y31: 선반
A32: L1/S1 | B32: L1 | C32: 좌측 벽면 | D32: 1 | E32: 일반약·여행·생활 | F32: 알레르기 정제·낮은 포장 | G32: 비염·알레르기 상담약 | H32: 지르텍정 알러샷연질캡슐 | I32: pd0001957 pd0002434 | J32: 대체 후보는 전체 상품 시트에서 동일 상품군 필터 | K32: 오픈 진열 | N32: 최상단 개구100mm, 계획 상품높이80mm 이하. 낮은 포장 또는 허용된 눕힘 진열만. 초과 시 S2 이하로 재배치. | O32: PDF p7 (2026-08-07) + 원본 2526품목; 판매·마진 데이터 없음 | P32: =COUNTIFS('05_상품별배치367'!$B$7:$B$373,A32,'05_상품별배치367'!$K$7:$K$373,">0") -> 2 | Q32: =SUMIFS('05_상품별배치367'!$K$7:$K$373,'05_상품별배치367'!$B$7:$B$373,A32) -> 2 | R32: =IF(Z32="",'06_집기치수20'!N12,Z32) -> 865 | S32: =IF(AA32="",'06_집기치수20'!O12,AA32) -> 270 | T32: 100 | U32: =IF(AB32="",'06_집기치수20'!P12,AB32-'06_집기치수20'!I12) -> 80 | V32: =IF(Q32=0,"",IF(COUNTIFS('05_상품별배치367'!$B$7:$B$373,A32,'05_상품별배치367'!$T$7:$T$373,"입력 대기")>0,"",SUMIFS('05_상품별배치367'!$S$7:$S$373,'05_상품별배치367'!$B$7:$B$373,A32))) | W32: =IF(Q32=0,"미진열",IF(COUNTIFS('05_상품별배치367'!$B$7:$B$373,A32,'05_상품별배치367'!$T$7:$T$373,"치수 초과")>0,"치수 초과",IF(COUNTIFS('05_상품별배치367'!$B$7:$B$373,A32,'05_상품별배치367'!$T$7:$T$373,"입력 대기")>0,"치수 입력 대기",IF(V32>R32,"폭 합계 초과","도면/실측 범위 내·현장확인")))) -> 치수 입력 대기 | X32: pd0001957 1F pd0002434 1F | Y32: 선반
A33: L1/S2 | B33: L1 | C33: 좌측 벽면 | D33: 2 | E33: 일반약·여행·생활 | F33: 감기 주간·야간 구분 | G33: 종합감기 상담약 | H33: 헤일리온_테라플루 데이타임 (포) 6P 콜대원 콜드큐시럽 헤일리온_테라플루 나이트타임 모드콜에스연질캡슐 | I33: pd0001958 pd0002435 pd0001966 pd0002536 | J33: 대체 후보는 전체 상품 시트에서 동일 상품군 필터 | K33: 오픈 진열 | N33: 상품명·규격은 원장 보존. 판매 단위·포장 치수·집기 실측 확인 후 배치 확정. | O33: PDF p7 (2026-08-07) + 원본 2526품목; 판매·마진 데이터 없음 | P33: =COUNTIFS('05_상품별배치367'!$B$7:$B$373,A33,'05_상품별배치367'!$K$7:$K$373,">0") -> 4 | Q33: =SUMIFS('05_상품별배치367'!$K$7:$K$373,'05_상품별배치367'!$B$7:$B$373,A33) -> 4 | R33: =IF(Z33="",'06_집기치수20'!N13,Z33) -> 865 | S33: =IF(AA33="",'06_집기치수20'!O13,AA33) -> 270 | T33: 220 | U33: =IF(AB33="",'06_집기치수20'!P13,AB33-'06_집기치수20'!I13) -> 200 | V33: =IF(Q33=0,"",IF(COUNTIFS('05_상품별배치367'!$B$7:$B$373,A33,'05_상품별배치367'!$T$7:$T$373,"입력 대기")>0,"",SUMIFS('05_상품별배치367'!$S$7:$S$373,'05_상품별배치367'!$B$7:$B$373,A33))) | W33: =IF(Q33=0,"미진열",IF(COUNTIFS('05_상품별배치367'!$B$7:$B$373,A33,'05_상품별배치367'!$T$7:$T$373,"치수 초과")>0,"치수 초과",IF(COUNTIFS('05_상품별배치367'!$B$7:$B$373,A33,'05_상품별배치367'!$T$7:$T$373,"입력 대기")>0,"치수 입력 대기",IF(V33>R33,"폭 합계 초과","도면/실측 범위 내·현장확인")))) -> 치수 입력 대기 | X33: pd0001958 1F pd0002435 1F pd0001966 1F pd0002536 1F | Y33: 선반
A34: L1/S3 | B34: L1 | C34: 좌측 벽면 | D34: 3 | E34: 일반약·여행·생활 | F34: 기침·인후 제형 | G34: 기침·인후 상담약 | H34: 용각산쿨과립(복숭아) 목앤스프레이 콜대원코프큐시럽 | I34: pd0002070 pd0002430 pd0002432 | J34: 대체 후보는 전체 상품 시트에서 동일 상품군 필터 | K34: 오픈 진열 | N34: 상품명·규격은 원장 보존. 판매 단위·포장 치수·집기 실측 확인 후 배치 확정. | O34: PDF p7 (2026-08-07) + 원본 2526품목; 판매·마진 데이터 없음 | P34: =COUNTIFS('05_상품별배치367'!$B$7:$B$373,A34,'05_상품별배치367'!$K$7:$K$373,">0") -> 3 | Q34: =SUMIFS('05_상품별배치367'!$K$7:$K$373,'05_상품별배치367'!$B$7:$B$373,A34) -> 3 | R34: =IF(Z34="",'06_집기치수20'!N14,Z34) -> 865 | S34: =IF(AA34="",'06_집기치수20'!O14,AA34) -> 270 | T34: 220 | U34: =IF(AB34="",'06_집기치수20'!P14,AB34-'06_집기치수20'!I14) -> 200 | V34: =IF(Q34=0,"",IF(COUNTIFS('05_상품별배치367'!$B$7:$B$373,A34,'05_상품별배치367'!$T$7:$T$373,"입력 대기")>0,"",SUMIFS('05_상품별배치367'!$S$7:$S$373,'05_상품별배치367'!$B$7:$B$373,A34))) | W34: =IF(Q34=0,"미진열",IF(COUNTIFS('05_상품별배치367'!$B$7:$B$373,A34,'05_상품별배치367'!$T$7:$T$373,"치수 초과")>0,"치수 초과",IF(COUNTIFS('05_상품별배치367'!$B$7:$B$373,A34,'05_상품별배치367'!$T$7:$T$373,"입력 대기")>0,"치수 입력 대기",IF(V34>R34,"폭 합계 초과","도면/실측 범위 내·현장확인")))) -> 치수 입력 대기 | X34: pd0002070 1F pd0002430 1F pd0002432 1F | Y34: 선반
A35: L1/S4 | B35: L1 | C35: 좌측 벽면 | D35: 4 | E35: 일반약·여행·생활 | F35: 코 증상 스프레이 | G35: 비염·알레르기 상담약 | H35: 코앤나잘스프레이 코앤쿨나잘스프레이 | I35: pd0002420 pd0002423 | J35: 대체 후보는 전체 상품 시트에서 동일 상품군 필터 | K35: 오픈 진열 | N35: 상품명·규격은 원장 보존. 판매 단위·포장 치수·집기 실측 확인 후 배치 확정. | O35: PDF p7 (2026-08-07) + 원본 2526품목; 판매·마진 데이터 없음 | P35: =COUNTIFS('05_상품별배치367'!$B$7:$B$373,A35,'05_상품별배치367'!$K$7:$K$373,">0") -> 2 | Q35: =SUMIFS('05_상품별배치367'!$K$7:$K$373,'05_상품별배치367'!$B$7:$B$373,A35) -> 2 | R35: =IF(Z35="",'06_집기치수20'!N15,Z35) -> 865 | S35: =IF(AA35="",'06_집기치수20'!O15,AA35) -> 270 | T35: 220 | U35: =IF(AB35="",'06_집기치수20'!P15,AB35-'06_집기치수20'!I15) -> 200 | V35: =IF(Q35=0,"",IF(COUNTIFS('05_상품별배치367'!$B$7:$B$373,A35,'05_상품별배치367'!$T$7:$T$373,"입력 대기")>0,"",SUMIFS('05_상품별배치367'!$S$7:$S$373,'05_상품별배치367'!$B$7:$B$373,A35))) | W35: =IF(Q35=0,"미진열",IF(COUNTIFS('05_상품별배치367'!$B$7:$B$373,A35,'05_상품별배치367'!$T$7:$T$373,"치수 초과")>0,"치수 초과",IF(COUNTIFS('05_상품별배치367'!$B$7:$B$373,A35,'05_상품별배치367'!$T$7:$T$373,"입력 대기")>0,"치수 입력 대기",IF(V35>R35,"폭 합계 초과","도면/실측 범위 내·현장확인")))) -> 치수 입력 대기 | X35: pd0002420 1F pd0002423 1F | Y35: 선반
A36: L1/S5 | B36: L1 | C36: 좌측 벽면 | D36: 5 | E36: 일반약·여행·생활 | F36: 어린이 여행 상담 | G36: 종합감기 상담약 / 기침·인후 상담약 / 비염·알레르기 상담약 | H36: 챔프콜드펜시럽 챔프코프액(포도향) 챔프노즈시럽(복숭아향) | I36: pd0002042 pd0002043 pd0002047 | J36: 대체 후보는 전체 상품 시트에서 동일 상품군 필터 | K36: 오픈 진열 | N36: 상품명·규격은 원장 보존. 판매 단위·포장 치수·집기 실측 확인 후 배치 확정. | O36: PDF p7 (2026-08-07) + 원본 2526품목; 판매·마진 데이터 없음 | P36: =COUNTIFS('05_상품별배치367'!$B$7:$B$373,A36,'05_상품별배치367'!$K$7:$K$373,">0") -> 3 | Q36: =SUMIFS('05_상품별배치367'!$K$7:$K$373,'05_상품별배치367'!$B$7:$B$373,A36) -> 3 | R36: =IF(Z36="",'06_집기치수20'!N16,Z36) -> 865 | S36: =IF(AA36="",'06_집기치수20'!O16,AA36) -> 270 | T36: 220 | U36: =IF(AB36="",'06_집기치수20'!P16,AB36-'06_집기치수20'!I16) -> 200 | V36: =IF(Q36=0,"",IF(COUNTIFS('05_상품별배치367'!$B$7:$B$373,A36,'05_상품별배치367'!$T$7:$T$373,"입력 대기")>0,"",SUMIFS('05_상품별배치367'!$S$7:$S$373,'05_상품별배치367'!$B$7:$B$373,A36))) | W36: =IF(Q36=0,"미진열",IF(COUNTIFS('05_상품별배치367'!$B$7:$B$373,A36,'05_상품별배치367'!$T$7:$T$373,"치수 초과")>0,"치수 초과",IF(COUNTIFS('05_상품별배치367'!$B$7:$B$373,A36,'05_상품별배치367'!$T$7:$T$373,"입력 대기")>0,"치수 입력 대기",IF(V36>R36,"폭 합계 초과","도면/실측 범위 내·현장확인")))) -> 치수 입력 대기 | X36: pd0002042 1F pd0002043 1F pd0002047 1F | Y36: 선반
A37: L2/S1 | B37: L2 | C37: 좌측 벽면 | D37: 1 | E37: 일반약·여행·생활 | F37: 소화 정제·낮은 포장 | G37: 소화·위장 상담약 | H37: 훼스탈슈퍼자임정 다제스캡슐 까스앤프리츄정 | I37: pd0002023 pd0002030 pd0002388 | J37: 대체 후보는 전체 상품 시트에서 동일 상품군 필터 | K37: 오픈 진열 | N37: 최상단 개구100mm, 계획 상품높이80mm 이하. 낮은 포장 또는 허용된 눕힘 진열만. 초과 시 S2 이하로 재배치. | O37: PDF p7 (2026-08-07) + 원본 2526품목; 판매·마진 데이터 없음 | P37: =COUNTIFS('05_상품별배치367'!$B$7:$B$373,A37,'05_상품별배치367'!$K$7:$K$373,">0") -> 3 | Q37: =SUMIFS('05_상품별배치367'!$K$7:$K$373,'05_상품별배치367'!$B$7:$B$373,A37) -> 3 | R37: =IF(Z37="",'06_집기치수20'!N12,Z37) -> 865 | S37: =IF(AA37="",'06_집기치수20'!O12,AA37) -> 270 | T37: 100 | U37: =IF(AB37="",'06_집기치수20'!P12,AB37-'06_집기치수20'!I12) -> 80 | V37: =IF(Q37=0,"",IF(COUNTIFS('05_상품별배치367'!$B$7:$B$373,A37,'05_상품별배치367'!$T$7:$T$373,"입력 대기")>0,"",SUMIFS('05_상품별배치367'!$S$7:$S$373,'05_상품별배치367'!$B$7:$B$373,A37))) | W37: =IF(Q37=0,"미진열",IF(COUNTIFS('05_상품별배치367'!$B$7:$B$373,A37,'05_상품별배치367'!$T$7:$T$373,"치수 초과")>0,"치수 초과",IF(COUNTIFS('05_상품별배치367'!$B$7:$B$373,A37,'05_상품별배치367'!$T$7:$T$373,"입력 대기")>0,"치수 입력 대기",IF(V37>R37,"폭 합계 초과","도면/실측 범위 내·현장확인")))) -> 치수 입력 대기 | X37: pd0002023 1F pd0002030 1F pd0002388 1F | Y37: 선반
A38: L2/S2 | B38: L2 | C38: 좌측 벽면 | D38: 2 | E38: 일반약·여행·생활 | F38: 소화·속 불편 액상 | G38: 소화·위장 상담약 | H38: 겔포스엘 현탁액 베나치오이지 트리겔현탁액 10ml*8p | I38: pd0002019 pd0002020 pd0002400 | J38: 대체 후보는 전체 상품 시트에서 동일 상품군 필터 | K38: 오픈 진열 | N38: 상품명·규격은 원장 보존. 판매 단위·포장 치수·집기 실측 확인 후 배치 확정. | O38: PDF p7 (2026-08-07) + 원본 2526품목; 판매·마진 데이터 없음 | P38: =COUNTIFS('05_상품별배치367'!$B$7:$B$373,A38,'05_상품별배치367'!$K$7:$K$373,">0") -> 3 | Q38: =SUMIFS('05_상품별배치367'!$K$7:$K$373,'05_상품별배치367'!$B$7:$B$373,A38) -> 3 | R38: =IF(Z38="",'06_집기치수20'!N13,Z38) -> 865 | S38: =IF(AA38="",'06_집기치수20'!O13,AA38) -> 270 | T38: 220 | U38: =IF(AB38="",'06_집기치수20'!P13,AB38-'06_집기치수20'!I13) -> 200 | V38: =IF(Q38=0,"",IF(COUNTIFS('05_상품별배치367'!$B$7:$B$373,A38,'05_상품별배치367'!$T$7:$T$373,"입력 대기")>0,"",SUMIFS('05_상품별배치367'!$S$7:$S$373,'05_상품별배치367'!$B$7:$B$373,A38))) | W38: =IF(Q38=0,"미진열",IF(COUNTIFS('05_상품별배치367'!$B$7:$B$373,A38,'05_상품별배치367'!$T$7:$T$373,"치수 초과")>0,"치수 초과",IF(COUNTIFS('05_상품별배치367'!$B$7:$B$373,A38,'05_상품별배치367'!$T$7:$T$373,"입력 대기")>0,"치수 입력 대기",IF(V38>R38,"폭 합계 초과","도면/실측 범위 내·현장확인")))) -> 치수 입력 대기 | X38: pd0002019 1F pd0002020 1F pd0002400 1F | Y38: 선반
A39: L2/S3 | B39: L2 | C39: 좌측 벽면 | D39: 3 | E39: 일반약·여행·생활 | F39: 설사 상담 | G39: 설사 상담약 | H39: 포타겔현탁액 로페시콘츄정 일양정로환에프정 | I39: pd0002393 pd0002391 pd0002539 | J39: 대체 후보는 전체 상품 시트에서 동일 상품군 필터 | K39: 오픈 진열 | N39: 상품명·규격은 원장 보존. 판매 단위·포장 치수·집기 실측 확인 후 배치 확정. | O39: PDF p7 (2026-08-07) + 원본 2526품목; 판매·마진 데이터 없음 | P39: =COUNTIFS('05_상품별배치367'!$B$7:$B$373,A39,'05_상품별배치367'!$K$7:$K$373,">0") -> 3 | Q39: =SUMIFS('05_상품별배치367'!$K$7:$K$373,'05_상품별배치367'!$B$7:$B$373,A39) -> 3 | R39: =IF(Z39="",'06_집기치수20'!N14,Z39) -> 865 | S39: =IF(AA39="",'06_집기치수20'!O14,AA39) -> 270 | T39: 220 | U39: =IF(AB39="",'06_집기치수20'!P14,AB39-'06_집기치수20'!I14) -> 200 | V39: =IF(Q39=0,"",IF(COUNTIFS('05_상품별배치367'!$B$7:$B$373,A39,'05_상품별배치367'!$T$7:$T$373,"입력 대기")>0,"",SUMIFS('05_상품별배치367'!$S$7:$S$373,'05_상품별배치367'!$B$7:$B$373,A39))) | W39: =IF(Q39=0,"미진열",IF(COUNTIFS('05_상품별배치367'!$B$7:$B$373,A39,'05_상품별배치367'!$T$7:$T$373,"치수 초과")>0,"치수 초과",IF(COUNTIFS('05_상품별배치367'!$B$7:$B$373,A39,'05_상품별배치367'!$T$7:$T$373,"입력 대기")>0,"치수 입력 대기",IF(V39>R39,"폭 합계 초과","도면/실측 범위 내·현장확인")))) -> 치수 입력 대기 | X39: pd0002393 1F pd0002391 1F pd0002539 1F | Y39: 선반
A40: L2/S4 | B40: L2 | C40: 좌측 벽면 | D40: 4 | E40: 일반약·여행·생활 | F40: 변비 상담 | G40: 변비 상담약 | H40: 굿모닝에스과립 한풍올가과립 | I40: pd0002035 pd0002031 | J40: 대체 후보는 전체 상품 시트에서 동일 상품군 필터 | K40: 오픈 진열 | N40: 상품명·규격은 원장 보존. 판매 단위·포장 치수·집기 실측 확인 후 배치 확정. | O40: PDF p7 (2026-08-07) + 원본 2526품목; 판매·마진 데이터 없음 | P40: =COUNTIFS('05_상품별배치367'!$B$7:$B$373,A40,'05_상품별배치367'!$K$7:$K$373,">0") -> 2 | Q40: =SUMIFS('05_상품별배치367'!$K$7:$K$373,'05_상품별배치367'!$B$7:$B$373,A40) -> 2 | R40: =IF(Z40="",'06_집기치수20'!N15,Z40) -> 865 | S40: =IF(AA40="",'06_집기치수20'!O15,AA40) -> 270 | T40: 220 | U40: =IF(AB40="",'06_집기치수20'!P15,AB40-'06_집기치수20'!I15) -> 200 | V40: =IF(Q40=0,"",IF(COUNTIFS('05_상품별배치367'!$B$7:$B$373,A40,'05_상품별배치367'!$T$7:$T$373,"입력 대기")>0,"",SUMIFS('05_상품별배치367'!$S$7:$S$373,'05_상품별배치367'!$B$7:$B$373,A40))) | W40: =IF(Q40=0,"미진열",IF(COUNTIFS('05_상품별배치367'!$B$7:$B$373,A40,'05_상품별배치367'!$T$7:$T$373,"치수 초과")>0,"치수 초과",IF(COUNTIFS('05_상품별배치367'!$B$7:$B$373,A40,'05_상품별배치367'!$T$7:$T$373,"입력 대기")>0,"치수 입력 대기",IF(V40>R40,"폭 합계 초과","도면/실측 범위 내·현장확인")))) -> 치수 입력 대기 | X40: pd0002035 1F pd0002031 1F | Y40: 선반
A41: L2/S5 | B41: L2 | C41: 좌측 벽면 | D41: 5 | E41: 일반약·여행·생활 | F41: 멀미·이동 상담 | G41: 멀미 상담약 | H41: 보나링츄어블정 멀스토구강용해필름 해피트립액 | I41: pd0002050 pd0002051 pd0002048 | J41: 대체 후보는 전체 상품 시트에서 동일 상품군 필터 | K41: 오픈 진열 | N41: 상품명·규격은 원장 보존. 판매 단위·포장 치수·집기 실측 확인 후 배치 확정. | O41: PDF p7 (2026-08-07) + 원본 2526품목; 판매·마진 데이터 없음 | P41: =COUNTIFS('05_상품별배치367'!$B$7:$B$373,A41,'05_상품별배치367'!$K$7:$K$373,">0") -> 3 | Q41: =SUMIFS('05_상품별배치367'!$K$7:$K$373,'05_상품별배치367'!$B$7:$B$373,A41) -> 3 | R41: =IF(Z41="",'06_집기치수20'!N16,Z41) -> 865 | S41: =IF(AA41="",'06_집기치수20'!O16,AA41) -> 270 | T41: 220 | U41: =IF(AB41="",'06_집기치수20'!P16,AB41-'06_집기치수20'!I16) -> 200 | V41: =IF(Q41=0,"",IF(COUNTIFS('05_상품별배치367'!$B$7:$B$373,A41,'05_상품별배치367'!$T$7:$T$373,"입력 대기")>0,"",SUMIFS('05_상품별배치367'!$S$7:$S$373,'05_상품별배치367'!$B$7:$B$373,A41))) | W41: =IF(Q41=0,"미진열",IF(COUNTIFS('05_상품별배치367'!$B$7:$B$373,A41,'05_상품별배치367'!$T$7:$T$373,"치수 초과")>0,"치수 초과",IF(COUNTIFS('05_상품별배치367'!$B$7:$B$373,A41,'05_상품별배치367'!$T$7:$T$373,"입력 대기")>0,"치수 입력 대기",IF(V41>R41,"폭 합계 초과","도면/실측 범위 내·현장확인")))) -> 치수 입력 대기 | X41: pd0002050 1F pd0002051 1F pd0002048 1F | Y41: 선반
A42: L3/S1 | B42: L3 | C42: 좌측 벽면 | D42: 1 | E42: 일반약·여행·생활 | F42: 해열·진통 소포장 | G42: 경구 해열·진통제 | H42: 타이레놀정500mg 이지엔6이브 탁센연질캡슐 탁센덱시연질캡슐 | I42: pd0001934 pd0001940 pd0001947 pd0001949 | J42: 대체 후보는 전체 상품 시트에서 동일 상품군 필터 | K42: 오픈 진열 | N42: 최상단 개구100mm, 계획 상품높이80mm 이하. 낮은 포장 또는 허용된 눕힘 진열만. 초과 시 S2 이하로 재배치. | O42: PDF p7 (2026-08-07) + 원본 2526품목; 판매·마진 데이터 없음 | P42: =COUNTIFS('05_상품별배치367'!$B$7:$B$373,A42,'05_상품별배치367'!$K$7:$K$373,">0") -> 4 | Q42: =SUMIFS('05_상품별배치367'!$K$7:$K$373,'05_상품별배치367'!$B$7:$B$373,A42) -> 5 | R42: =IF(Z42="",'06_집기치수20'!N12,Z42) -> 865 | S42: =IF(AA42="",'06_집기치수20'!O12,AA42) -> 270 | T42: 100 | U42: =IF(AB42="",'06_집기치수20'!P12,AB42-'06_집기치수20'!I12) -> 80 | V42: =IF(Q42=0,"",IF(COUNTIFS('05_상품별배치367'!$B$7:$B$373,A42,'05_상품별배치367'!$T$7:$T$373,"입력 대기")>0,"",SUMIFS('05_상품별배치367'!$S$7:$S$373,'05_상품별배치367'!$B$7:$B$373,A42))) | W42: =IF(Q42=0,"미진열",IF(COUNTIFS('05_상품별배치367'!$B$7:$B$373,A42,'05_상품별배치367'!$T$7:$T$373,"치수 초과")>0,"치수 초과",IF(COUNTIFS('05_상품별배치367'!$B$7:$B$373,A42,'05_상품별배치367'!$T$7:$T$373,"입력 대기")>0,"치수 입력 대기",IF(V42>R42,"폭 합계 초과","도면/실측 범위 내·현장확인")))) -> 치수 입력 대기 | X42: pd0001934 2F pd0001940 1F pd0001947 1F pd0001949 1F | Y42: 선반
A43: L3/S2 | B43: L3 | C43: 좌측 벽면 | D43: 2 | E43: 일반약·여행·생활 | F43: 파스 기본·롱 규격 | G43: 파스·바르는 진통제 | H43: 신신파스아렉스(중) 신신파스플렉스 아렉스마일드 신신파스 아렉스 롱 | I43: pd0001890 pd0001875 pd0001883 | J43: 대체 후보는 전체 상품 시트에서 동일 상품군 필터 | K43: 오픈 진열 | N43: 상품명·규격은 원장 보존. 판매 단위·포장 치수·집기 실측 확인 후 배치 확정. | O43: PDF p7 (2026-08-07) + 원본 2526품목; 판매·마진 데이터 없음 | P43: =COUNTIFS('05_상품별배치367'!$B$7:$B$373,A43,'05_상품별배치367'!$K$7:$K$373,">0") -> 3 | Q43: =SUMIFS('05_상품별배치367'!$K$7:$K$373,'05_상품별배치367'!$B$7:$B$373,A43) -> 4 | R43: =IF(Z43="",'06_집기치수20'!N13,Z43) -> 865 | S43: =IF(AA43="",'06_집기치수20'!O13,AA43) -> 270 | T43: 220 | U43: =IF(AB43="",'06_집기치수20'!P13,AB43-'06_집기치수20'!I13) -> 200 | V43: =IF(Q43=0,"",IF(COUNTIFS('05_상품별배치367'!$B$7:$B$373,A43,'05_상품별배치367'!$T$7:$T$373,"입력 대기")>0,"",SUMIFS('05_상품별배치367'!$S$7:$S$373,'05_상품별배치367'!$B$7:$B$373,A43))) | W43: =IF(Q43=0,"미진열",IF(COUNTIFS('05_상품별배치367'!$B$7:$B$373,A43,'05_상품별배치367'!$T$7:$T$373,"치수 초과")>0,"치수 초과",IF(COUNTIFS('05_상품별배치367'!$B$7:$B$373,A43,'05_상품별배치367'!$T$7:$T$373,"입력 대기")>0,"치수 입력 대기",IF(V43>R43,"폭 합계 초과","도면/실측 범위 내·현장확인")))) -> 치수 입력 대기 | X43: pd0001890 2F pd0001875 1F pd0001883 1F | Y43: 선반
...

Sheet 03_상품분류2526
E1: j
A2: 전체 상품 2,526행 · 도입 권장·중요도·페이싱
A3: 원본명·규격·공급코드 보존 | A 핵심 / B 보완 / T 시험 / C 대체 / H 확인 / N 초도 제외 | O~Q는 배치표 연동 | V~X는 소매포장 실측 mm
A6: 원본 공급코드 | B6: 원본 행 | C6: 원본 상품명 | D6: 원본 규격 | E6: 대분류 | F6: 운영 상품군 | G6: 권장 주 진열 | H6: 구체 선반 | I6: 취급 권장 | J6: 확정 위치 | K6: 분류·표시 대조 | L6: 분류·원본 이슈 | M6: 중요도 | N6: 오픈 선정 | O6: 본진 F | P6: 추가 F | Q6: 총 F | R6: 채택시 시작F | S6: 선정·보류 사유 | T6: 브랜드 검토 | U6: 중복 대조코드 | V6: 포장 가로 mm | W6: 포장 높이 mm | X6: 포장 깊이 mm | Y6: 소매단위 확인 | Z6: 확정 바코드 | AA6: 최종 취급결정
A7: pd0002494 | B7: 2468 | C7: (논현)광동원탕 | D7: 100ml | E7: 일반 상비·상담약 | F7: 자양강장·한방 상담약 | G7: W4 | I7: 대체 후보 | K7: 의약품 후보·허가 대조 | L7: 매입가 0 의미 확인 | M7: C | N7: 예 | O7: =SUMIFS('05_상품별배치367'!$K$7:$K$373,'05_상품별배치367'!$E$7:$E$373,A7,'05_상품별배치367'!$H$7:$H$373,"본진") -> 0 | P7: =SUMIFS('05_상품별배치367'!$K$7:$K$373,'05_상품별배치367'!$E$7:$E$373,A7,'05_상품별배치367'!$H$7:$H$373,"추가 진열") -> 0 | Q7: =O7+P7 -> 0 | R7: 1 | S7: 자양강장·한방 상담약 기본 선정품의 대안. 동시 입고보다 가격·제형·공급 차이가 있을 때 교체. | T7: 원본명 참고·브랜드 대조 | Y7: 현행 공급·바코드 대조 | AA7: 미확정
A8: pd0002347 | B8: 2337 | C8: (리쥬올)PDRN리쥬비네이팅크림 | D8: 30mL | E8: 스킨케어 | F8: PDRN 스킨케어 | G8: G5-D-1 | H8: G5-D-1/S2 | I8: 오픈 핵심 | K8: 화장품 후보·표시 확인 | L8: 매입가 0 의미 확인 | M8: A | N8: 예 | O8: =SUMIFS('05_상품별배치367'!$K$7:$K$373,'05_상품별배치367'!$E$7:$E$373,A8,'05_상품별배치367'!$H$7:$H$373,"본진") -> 2 | P8: =SUMIFS('05_상품별배치367'!$K$7:$K$373,'05_상품별배치367'!$E$7:$E$373,A8,'05_상품별배치367'!$H$7:$H$373,"추가 진열") -> 1 | Q8: =O8+P8 -> 3 | R8: 2 | S8: 기존 핵심 수요 또는 약국 기본 상담 구색. 우선 도입 제안. | T8: 닥터리쥬올 | Y8: 현행 공급·바코드 대조 | AA8: 미확정
A9: pd0002346 | B9: 2336 | C9: (리쥬올)어드밴스드 레티노멜라세럼 | D9: 50mL | E9: 스킨케어 | F9: 톤·브라이트닝 스킨케어 | G9: G3-D-2 | H9: G3-D-2/S3 | I9: 오픈 핵심 | K9: 화장품 후보·표시 확인 | L9: 매입가 0 의미 확인 | M9: A | N9: 예 | O9: =SUMIFS('05_상품별배치367'!$K$7:$K$373,'05_상품별배치367'!$E$7:$E$373,A9,'05_상품별배치367'!$H$7:$H$373,"본진") -> 1 | P9: =SUMIFS('05_상품별배치367'!$K$7:$K$373,'05_상품별배치367'!$E$7:$E$373,A9,'05_상품별배치367'!$H$7:$H$373,"추가 진열") -> 0 | Q9: =O9+P9 -> 1 | R9: 1 | S9: 기존 핵심 수요 또는 약국 기본 상담 구색. 우선 도입 제안. | T9: 닥터리쥬올 | Y9: 현행 공급·바코드 대조 | AA9: 미확정
A10: pd0002513 | B10: 2486 | C10: (신)니조랄2%액 | D10: 100ml | E10: 일반 상비·상담약 | F10: 탈모·두피 상담약 | G10: G3-U-1 | H10: G3-U-1/S3 | I10: 오픈 핵심 | K10: 의약품 후보·허가 대조 | L10: 매입가 0 의미 확인 | M10: A | N10: 예 | O10: =SUMIFS('05_상품별배치367'!$K$7:$K$373,'05_상품별배치367'!$E$7:$E$373,A10,'05_상품별배치367'!$H$7:$H$373,"본진") -> 1 | P10: =SUMIFS('05_상품별배치367'!$K$7:$K$373,'05_상품별배치367'!$E$7:$E$373,A10,'05_상품별배치367'!$H$7:$H$373,"추가 진열") -> 1 | Q10: =O10+P10 -> 2 | R10: 1 | S10: 기존 핵심 수요 또는 약국 기본 상담 구색. 우선 도입 제안. | T10: 원본명 참고·브랜드 대조 | Y10: 현행 공급·바코드 대조 | AA10: 미확정
